2025-03-17 14:26:05,465 - __main__ - INFO - MongoDB connection established successfully
2025-03-17 14:26:05,666 - __main__ - INFO - Model loaded successfully
2025-03-17 14:26:05,666 - __main__ - INFO - Scaler loaded successfully
2025-03-17 14:26:05,666 - __main__ - INFO - Label encoder loaded successfully
2025-03-17 14:26:05,672 - __main__ - INFO - Starting prediction service on http://localhost:5000
2025-03-17 14:26:05,688 - werkzeug - INFO - [31m[1mWARNING: This is a development server. Do not use it in a production deployment. Use a production WSGI server instead.[0m
 * Running on all addresses (0.0.0.0)
 * Running on http://127.0.0.1:5000
 * Running on http://172.28.4.140:5000
2025-03-17 14:26:05,688 - werkzeug - INFO - [33mPress CTRL+C to quit[0m
2025-03-17 14:26:09,838 - __main__ - WARNING - Failed to retrieve dataset size: Collection objects do not implement truth value testing or bool(). Please compare with None instead: collection is not None
2025-03-17 14:26:09,840 - __main__ - ERROR - Error in calculate_performance_metrics_from_recent_data: Collection objects do not implement truth value testing or bool(). Please compare with None instead: collection is not None
2025-03-17 14:26:09,841 - werkzeug - INFO - 127.0.0.1 - - [17/Mar/2025 14:26:09] "GET /api/dashboard/model-metrics HTTP/1.1" 200 -
2025-03-17 14:26:09,848 - __main__ - INFO - No training_params.json file found, using default values
2025-03-17 14:26:09,860 - __main__ - ERROR - Unhandled error in get_model_config: Object of type int64 is not JSON serializable
Traceback (most recent call last):
  File "D:\research\adhd-assessment-system\backend\mlmodels\it21288326\retrain_model.py", line 2351, in get_model_config
    return jsonify(response), 200
           ^^^^^^^^^^^^^^^^^
  File "D:\research\adhd-assessment-system\backend\mlmodels\it21288326\venv\Lib\site-packages\flask\json\__init__.py", line 170, in jsonify
    return current_app.json.response(*args, **kwargs)  # type: ignore[return-value]
           ^^^^^^^^^^^^^^^^^^^^^^^^^^^^^^^^^^^^^^^^^^
  File "D:\research\adhd-assessment-system\backend\mlmodels\it21288326\venv\Lib\site-packages\flask\json\provider.py", line 214, in response
    f"{self.dumps(obj, **dump_args)}\n", mimetype=self.mimetype
       ^^^^^^^^^^^^^^^^^^^^^^^^^^^^
  File "D:\research\adhd-assessment-system\backend\mlmodels\it21288326\venv\Lib\site-packages\flask\json\provider.py", line 179, in dumps
    return json.dumps(obj, **kwargs)
           ^^^^^^^^^^^^^^^^^^^^^^^^^
  File "C:\Users\User\AppData\Local\Programs\Python\Python311\Lib\json\__init__.py", line 238, in dumps
    **kw).encode(obj)
          ^^^^^^^^^^^
  File "C:\Users\User\AppData\Local\Programs\Python\Python311\Lib\json\encoder.py", line 200, in encode
    chunks = self.iterencode(o, _one_shot=True)
             ^^^^^^^^^^^^^^^^^^^^^^^^^^^^^^^^^^
  File "C:\Users\User\AppData\Local\Programs\Python\Python311\Lib\json\encoder.py", line 258, in iterencode
    return _iterencode(o, 0)
           ^^^^^^^^^^^^^^^^^
  File "D:\research\adhd-assessment-system\backend\mlmodels\it21288326\venv\Lib\site-packages\flask\json\provider.py", line 121, in _default
    raise TypeError(f"Object of type {type(o).__name__} is not JSON serializable")
TypeError: Object of type int64 is not JSON serializable

2025-03-17 14:26:09,861 - werkzeug - INFO - 127.0.0.1 - - [17/Mar/2025 14:26:09] "[35m[1mGET /api/dashboard/model-config HTTP/1.1[0m" 500 -
2025-03-17 14:26:10,132 - werkzeug - INFO - 127.0.0.1 - - [17/Mar/2025 14:26:10] "GET /api/dashboard/system-status HTTP/1.1" 200 -
2025-03-17 14:26:11,793 - werkzeug - INFO - 127.0.0.1 - - [17/Mar/2025 14:26:11] "GET /api/dashboard/prediction-metrics HTTP/1.1" 200 -
2025-03-17 14:26:12,729 - werkzeug - INFO - 127.0.0.1 - - [17/Mar/2025 14:26:12] "GET /api/dashboard/assessment-stats HTTP/1.1" 200 -
2025-03-17 14:26:15,296 - werkzeug - INFO - 127.0.0.1 - - [17/Mar/2025 14:26:15] "GET /api/dashboard/system-status HTTP/1.1" 200 -
2025-03-17 14:26:15,360 - __main__ - WARNING - Failed to retrieve dataset size: Collection objects do not implement truth value testing or bool(). Please compare with None instead: collection is not None
2025-03-17 14:26:15,360 - __main__ - ERROR - Error in calculate_performance_metrics_from_recent_data: Collection objects do not implement truth value testing or bool(). Please compare with None instead: collection is not None
2025-03-17 14:26:15,375 - werkzeug - INFO - 127.0.0.1 - - [17/Mar/2025 14:26:15] "GET /api/dashboard/model-metrics HTTP/1.1" 200 -
2025-03-17 14:26:15,375 - __main__ - INFO - No training_params.json file found, using default values
2025-03-17 14:26:15,385 - __main__ - ERROR - Unhandled error in get_model_config: Object of type int64 is not JSON serializable
Traceback (most recent call last):
  File "D:\research\adhd-assessment-system\backend\mlmodels\it21288326\retrain_model.py", line 2351, in get_model_config
    return jsonify(response), 200
           ^^^^^^^^^^^^^^^^^
  File "D:\research\adhd-assessment-system\backend\mlmodels\it21288326\venv\Lib\site-packages\flask\json\__init__.py", line 170, in jsonify
    return current_app.json.response(*args, **kwargs)  # type: ignore[return-value]
           ^^^^^^^^^^^^^^^^^^^^^^^^^^^^^^^^^^^^^^^^^^
  File "D:\research\adhd-assessment-system\backend\mlmodels\it21288326\venv\Lib\site-packages\flask\json\provider.py", line 214, in response
    f"{self.dumps(obj, **dump_args)}\n", mimetype=self.mimetype
       ^^^^^^^^^^^^^^^^^^^^^^^^^^^^
  File "D:\research\adhd-assessment-system\backend\mlmodels\it21288326\venv\Lib\site-packages\flask\json\provider.py", line 179, in dumps
    return json.dumps(obj, **kwargs)
           ^^^^^^^^^^^^^^^^^^^^^^^^^
  File "C:\Users\User\AppData\Local\Programs\Python\Python311\Lib\json\__init__.py", line 238, in dumps
    **kw).encode(obj)
          ^^^^^^^^^^^
  File "C:\Users\User\AppData\Local\Programs\Python\Python311\Lib\json\encoder.py", line 200, in encode
    chunks = self.iterencode(o, _one_shot=True)
             ^^^^^^^^^^^^^^^^^^^^^^^^^^^^^^^^^^
  File "C:\Users\User\AppData\Local\Programs\Python\Python311\Lib\json\encoder.py", line 258, in iterencode
    return _iterencode(o, 0)
           ^^^^^^^^^^^^^^^^^
  File "D:\research\adhd-assessment-system\backend\mlmodels\it21288326\venv\Lib\site-packages\flask\json\provider.py", line 121, in _default
    raise TypeError(f"Object of type {type(o).__name__} is not JSON serializable")
TypeError: Object of type int64 is not JSON serializable

2025-03-17 14:26:15,391 - werkzeug - INFO - 127.0.0.1 - - [17/Mar/2025 14:26:15] "[35m[1mGET /api/dashboard/model-config HTTP/1.1[0m" 500 -
2025-03-17 14:26:15,693 - __main__ - WARNING - Failed to retrieve dataset size: Collection objects do not implement truth value testing or bool(). Please compare with None instead: collection is not None
2025-03-17 14:26:15,693 - __main__ - ERROR - Error in calculate_performance_metrics_from_recent_data: Collection objects do not implement truth value testing or bool(). Please compare with None instead: collection is not None
2025-03-17 14:26:15,700 - werkzeug - INFO - 127.0.0.1 - - [17/Mar/2025 14:26:15] "GET /api/dashboard/model-metrics HTTP/1.1" 200 -
2025-03-17 14:26:15,702 - __main__ - INFO - No training_params.json file found, using default values
2025-03-17 14:26:15,709 - __main__ - ERROR - Unhandled error in get_model_config: Object of type int64 is not JSON serializable
Traceback (most recent call last):
  File "D:\research\adhd-assessment-system\backend\mlmodels\it21288326\retrain_model.py", line 2351, in get_model_config
    return jsonify(response), 200
           ^^^^^^^^^^^^^^^^^
  File "D:\research\adhd-assessment-system\backend\mlmodels\it21288326\venv\Lib\site-packages\flask\json\__init__.py", line 170, in jsonify
    return current_app.json.response(*args, **kwargs)  # type: ignore[return-value]
           ^^^^^^^^^^^^^^^^^^^^^^^^^^^^^^^^^^^^^^^^^^
  File "D:\research\adhd-assessment-system\backend\mlmodels\it21288326\venv\Lib\site-packages\flask\json\provider.py", line 214, in response
    f"{self.dumps(obj, **dump_args)}\n", mimetype=self.mimetype
       ^^^^^^^^^^^^^^^^^^^^^^^^^^^^
  File "D:\research\adhd-assessment-system\backend\mlmodels\it21288326\venv\Lib\site-packages\flask\json\provider.py", line 179, in dumps
    return json.dumps(obj, **kwargs)
           ^^^^^^^^^^^^^^^^^^^^^^^^^
  File "C:\Users\User\AppData\Local\Programs\Python\Python311\Lib\json\__init__.py", line 238, in dumps
    **kw).encode(obj)
          ^^^^^^^^^^^
  File "C:\Users\User\AppData\Local\Programs\Python\Python311\Lib\json\encoder.py", line 200, in encode
    chunks = self.iterencode(o, _one_shot=True)
             ^^^^^^^^^^^^^^^^^^^^^^^^^^^^^^^^^^
  File "C:\Users\User\AppData\Local\Programs\Python\Python311\Lib\json\encoder.py", line 258, in iterencode
    return _iterencode(o, 0)
           ^^^^^^^^^^^^^^^^^
  File "D:\research\adhd-assessment-system\backend\mlmodels\it21288326\venv\Lib\site-packages\flask\json\provider.py", line 121, in _default
    raise TypeError(f"Object of type {type(o).__name__} is not JSON serializable")
TypeError: Object of type int64 is not JSON serializable

2025-03-17 14:26:15,709 - werkzeug - INFO - 127.0.0.1 - - [17/Mar/2025 14:26:15] "[35m[1mGET /api/dashboard/model-config HTTP/1.1[0m" 500 -
2025-03-17 14:26:15,789 - werkzeug - INFO - 127.0.0.1 - - [17/Mar/2025 14:26:15] "GET /api/dashboard/prediction-metrics HTTP/1.1" 200 -
2025-03-17 14:26:15,825 - werkzeug - INFO - 127.0.0.1 - - [17/Mar/2025 14:26:15] "GET /api/dashboard/system-status HTTP/1.1" 200 -
2025-03-17 14:26:16,427 - werkzeug - INFO - 127.0.0.1 - - [17/Mar/2025 14:26:16] "GET /api/dashboard/prediction-metrics HTTP/1.1" 200 -
2025-03-17 14:26:16,429 - werkzeug - INFO - 127.0.0.1 - - [17/Mar/2025 14:26:16] "GET /api/dashboard/assessment-stats HTTP/1.1" 200 -
2025-03-17 14:26:17,855 - werkzeug - INFO - 127.0.0.1 - - [17/Mar/2025 14:26:17] "GET /api/dashboard/assessment-stats HTTP/1.1" 200 -
2025-03-17 14:32:21,876 - __main__ - WARNING - Failed to retrieve dataset size: Collection objects do not implement truth value testing or bool(). Please compare with None instead: collection is not None
2025-03-17 14:32:21,876 - __main__ - ERROR - Error in calculate_performance_metrics_from_recent_data: Collection objects do not implement truth value testing or bool(). Please compare with None instead: collection is not None
2025-03-17 14:32:21,886 - werkzeug - INFO - 127.0.0.1 - - [17/Mar/2025 14:32:21] "GET /api/dashboard/model-metrics HTTP/1.1" 200 -
2025-03-17 14:32:21,886 - __main__ - INFO - No training_params.json file found, using default values
2025-03-17 14:32:21,955 - __main__ - ERROR - Unhandled error in get_model_config: Object of type int64 is not JSON serializable
Traceback (most recent call last):
  File "D:\research\adhd-assessment-system\backend\mlmodels\it21288326\retrain_model.py", line 2351, in get_model_config
    return jsonify(response), 200
           ^^^^^^^^^^^^^^^^^
  File "D:\research\adhd-assessment-system\backend\mlmodels\it21288326\venv\Lib\site-packages\flask\json\__init__.py", line 170, in jsonify
    return current_app.json.response(*args, **kwargs)  # type: ignore[return-value]
           ^^^^^^^^^^^^^^^^^^^^^^^^^^^^^^^^^^^^^^^^^^
  File "D:\research\adhd-assessment-system\backend\mlmodels\it21288326\venv\Lib\site-packages\flask\json\provider.py", line 214, in response
    f"{self.dumps(obj, **dump_args)}\n", mimetype=self.mimetype
       ^^^^^^^^^^^^^^^^^^^^^^^^^^^^
  File "D:\research\adhd-assessment-system\backend\mlmodels\it21288326\venv\Lib\site-packages\flask\json\provider.py", line 179, in dumps
    return json.dumps(obj, **kwargs)
           ^^^^^^^^^^^^^^^^^^^^^^^^^
  File "C:\Users\User\AppData\Local\Programs\Python\Python311\Lib\json\__init__.py", line 238, in dumps
    **kw).encode(obj)
          ^^^^^^^^^^^
  File "C:\Users\User\AppData\Local\Programs\Python\Python311\Lib\json\encoder.py", line 200, in encode
    chunks = self.iterencode(o, _one_shot=True)
             ^^^^^^^^^^^^^^^^^^^^^^^^^^^^^^^^^^
  File "C:\Users\User\AppData\Local\Programs\Python\Python311\Lib\json\encoder.py", line 258, in iterencode
    return _iterencode(o, 0)
           ^^^^^^^^^^^^^^^^^
  File "D:\research\adhd-assessment-system\backend\mlmodels\it21288326\venv\Lib\site-packages\flask\json\provider.py", line 121, in _default
    raise TypeError(f"Object of type {type(o).__name__} is not JSON serializable")
TypeError: Object of type int64 is not JSON serializable

2025-03-17 14:32:21,955 - werkzeug - INFO - 127.0.0.1 - - [17/Mar/2025 14:32:21] "[35m[1mGET /api/dashboard/model-config HTTP/1.1[0m" 500 -
2025-03-17 14:32:22,018 - werkzeug - INFO - 127.0.0.1 - - [17/Mar/2025 14:32:22] "GET /api/dashboard/system-status HTTP/1.1" 200 -
2025-03-17 14:32:22,226 - werkzeug - INFO - 127.0.0.1 - - [17/Mar/2025 14:32:22] "GET /api/dashboard/prediction-metrics HTTP/1.1" 200 -
2025-03-17 14:32:22,952 - werkzeug - INFO - 127.0.0.1 - - [17/Mar/2025 14:32:22] "GET /api/dashboard/assessment-stats HTTP/1.1" 200 -
2025-03-17 14:37:39,162 - __main__ - INFO - MongoDB connection established successfully
2025-03-17 14:37:39,344 - __main__ - INFO - Model loaded successfully
2025-03-17 14:37:39,347 - __main__ - INFO - Scaler loaded successfully
2025-03-17 14:37:39,347 - __main__ - INFO - Label encoder loaded successfully
2025-03-17 14:37:39,347 - __main__ - INFO - Starting prediction service on http://localhost:5000
2025-03-17 14:37:39,361 - werkzeug - INFO - [31m[1mWARNING: This is a development server. Do not use it in a production deployment. Use a production WSGI server instead.[0m
 * Running on all addresses (0.0.0.0)
 * Running on http://127.0.0.1:5000
 * Running on http://172.28.4.140:5000
2025-03-17 14:37:39,361 - werkzeug - INFO - [33mPress CTRL+C to quit[0m
2025-03-17 14:37:48,800 - __main__ - WARNING - Failed to retrieve dataset size: Collection objects do not implement truth value testing or bool(). Please compare with None instead: collection is not None
2025-03-17 14:37:48,800 - __main__ - ERROR - Error in calculate_performance_metrics_from_recent_data: Collection objects do not implement truth value testing or bool(). Please compare with None instead: collection is not None
2025-03-17 14:37:48,811 - werkzeug - INFO - 127.0.0.1 - - [17/Mar/2025 14:37:48] "GET /api/dashboard/model-metrics HTTP/1.1" 200 -
2025-03-17 14:37:48,811 - __main__ - INFO - No training_params.json file found, using default values
2025-03-17 14:37:48,811 - retrain_model - ERROR - Exception on /api/dashboard/model-config [GET]
Traceback (most recent call last):
  File "D:\research\adhd-assessment-system\backend\mlmodels\it21288326\venv\Lib\site-packages\flask\app.py", line 1511, in wsgi_app
    response = self.full_dispatch_request()
               ^^^^^^^^^^^^^^^^^^^^^^^^^^^^
  File "D:\research\adhd-assessment-system\backend\mlmodels\it21288326\venv\Lib\site-packages\flask\app.py", line 919, in full_dispatch_request
    rv = self.handle_user_exception(e)
         ^^^^^^^^^^^^^^^^^^^^^^^^^^^^^
  File "D:\research\adhd-assessment-system\backend\mlmodels\it21288326\venv\Lib\site-packages\flask_cors\extension.py", line 176, in wrapped_function
    return cors_after_request(app.make_response(f(*args, **kwargs)))
                                                ^^^^^^^^^^^^^^^^^^
  File "D:\research\adhd-assessment-system\backend\mlmodels\it21288326\venv\Lib\site-packages\flask\app.py", line 917, in full_dispatch_request
    rv = self.dispatch_request()
         ^^^^^^^^^^^^^^^^^^^^^^^
  File "D:\research\adhd-assessment-system\backend\mlmodels\it21288326\venv\Lib\site-packages\flask\app.py", line 902, in dispatch_request
    return self.ensure_sync(self.view_functions[rule.endpoint])(**view_args)  # type: ignore[no-any-return]
           ^^^^^^^^^^^^^^^^^^^^^^^^^^^^^^^^^^^^^^^^^^^^^^^^^^^^^^^^^^^^^^^^^
  File "D:\research\adhd-assessment-system\backend\mlmodels\it21288326\retrain_model.py", line 2393, in get_model_config
    "timestamp": datetime.datetime.now().isoformat()
                 ^^^^^^^^^^^^^^^^^
AttributeError: type object 'datetime.datetime' has no attribute 'datetime'
2025-03-17 14:37:48,827 - werkzeug - INFO - 127.0.0.1 - - [17/Mar/2025 14:37:48] "[35m[1mGET /api/dashboard/model-config HTTP/1.1[0m" 500 -
2025-03-17 14:37:49,052 - werkzeug - INFO - 127.0.0.1 - - [17/Mar/2025 14:37:49] "GET /api/dashboard/system-status HTTP/1.1" 200 -
2025-03-17 14:37:51,112 - werkzeug - INFO - 127.0.0.1 - - [17/Mar/2025 14:37:51] "GET /api/dashboard/prediction-metrics HTTP/1.1" 200 -
2025-03-17 14:37:51,707 - werkzeug - INFO - 127.0.0.1 - - [17/Mar/2025 14:37:51] "GET /api/dashboard/assessment-stats HTTP/1.1" 200 -
2025-03-17 14:37:53,659 - werkzeug - INFO - 127.0.0.1 - - [17/Mar/2025 14:37:53] "GET /api/dashboard/system-status HTTP/1.1" 200 -
2025-03-17 14:37:53,841 - __main__ - WARNING - Failed to retrieve dataset size: Collection objects do not implement truth value testing or bool(). Please compare with None instead: collection is not None
2025-03-17 14:37:53,843 - __main__ - ERROR - Error in calculate_performance_metrics_from_recent_data: Collection objects do not implement truth value testing or bool(). Please compare with None instead: collection is not None
2025-03-17 14:37:53,845 - __main__ - INFO - No training_params.json file found, using default values
2025-03-17 14:37:53,847 - werkzeug - INFO - 127.0.0.1 - - [17/Mar/2025 14:37:53] "GET /api/dashboard/model-metrics HTTP/1.1" 200 -
2025-03-17 14:37:53,847 - retrain_model - ERROR - Exception on /api/dashboard/model-config [GET]
Traceback (most recent call last):
  File "D:\research\adhd-assessment-system\backend\mlmodels\it21288326\venv\Lib\site-packages\flask\app.py", line 1511, in wsgi_app
    response = self.full_dispatch_request()
               ^^^^^^^^^^^^^^^^^^^^^^^^^^^^
  File "D:\research\adhd-assessment-system\backend\mlmodels\it21288326\venv\Lib\site-packages\flask\app.py", line 919, in full_dispatch_request
    rv = self.handle_user_exception(e)
         ^^^^^^^^^^^^^^^^^^^^^^^^^^^^^
  File "D:\research\adhd-assessment-system\backend\mlmodels\it21288326\venv\Lib\site-packages\flask_cors\extension.py", line 176, in wrapped_function
    return cors_after_request(app.make_response(f(*args, **kwargs)))
                                                ^^^^^^^^^^^^^^^^^^
  File "D:\research\adhd-assessment-system\backend\mlmodels\it21288326\venv\Lib\site-packages\flask\app.py", line 917, in full_dispatch_request
    rv = self.dispatch_request()
         ^^^^^^^^^^^^^^^^^^^^^^^
  File "D:\research\adhd-assessment-system\backend\mlmodels\it21288326\venv\Lib\site-packages\flask\app.py", line 902, in dispatch_request
    return self.ensure_sync(self.view_functions[rule.endpoint])(**view_args)  # type: ignore[no-any-return]
           ^^^^^^^^^^^^^^^^^^^^^^^^^^^^^^^^^^^^^^^^^^^^^^^^^^^^^^^^^^^^^^^^^
  File "D:\research\adhd-assessment-system\backend\mlmodels\it21288326\retrain_model.py", line 2393, in get_model_config
    "timestamp": datetime.datetime.now().isoformat()
                 ^^^^^^^^^^^^^^^^^
AttributeError: type object 'datetime.datetime' has no attribute 'datetime'
2025-03-17 14:37:53,853 - werkzeug - INFO - 127.0.0.1 - - [17/Mar/2025 14:37:53] "[35m[1mGET /api/dashboard/model-config HTTP/1.1[0m" 500 -
2025-03-17 14:37:54,126 - werkzeug - INFO - 127.0.0.1 - - [17/Mar/2025 14:37:54] "GET /api/dashboard/prediction-metrics HTTP/1.1" 200 -
2025-03-17 14:37:54,163 - __main__ - WARNING - Failed to retrieve dataset size: Collection objects do not implement truth value testing or bool(). Please compare with None instead: collection is not None
2025-03-17 14:37:54,166 - __main__ - ERROR - Error in calculate_performance_metrics_from_recent_data: Collection objects do not implement truth value testing or bool(). Please compare with None instead: collection is not None
2025-03-17 14:37:54,168 - werkzeug - INFO - 127.0.0.1 - - [17/Mar/2025 14:37:54] "GET /api/dashboard/model-metrics HTTP/1.1" 200 -
2025-03-17 14:37:54,170 - __main__ - INFO - No training_params.json file found, using default values
2025-03-17 14:37:54,172 - retrain_model - ERROR - Exception on /api/dashboard/model-config [GET]
Traceback (most recent call last):
  File "D:\research\adhd-assessment-system\backend\mlmodels\it21288326\venv\Lib\site-packages\flask\app.py", line 1511, in wsgi_app
    response = self.full_dispatch_request()
               ^^^^^^^^^^^^^^^^^^^^^^^^^^^^
  File "D:\research\adhd-assessment-system\backend\mlmodels\it21288326\venv\Lib\site-packages\flask\app.py", line 919, in full_dispatch_request
    rv = self.handle_user_exception(e)
         ^^^^^^^^^^^^^^^^^^^^^^^^^^^^^
  File "D:\research\adhd-assessment-system\backend\mlmodels\it21288326\venv\Lib\site-packages\flask_cors\extension.py", line 176, in wrapped_function
    return cors_after_request(app.make_response(f(*args, **kwargs)))
                                                ^^^^^^^^^^^^^^^^^^
  File "D:\research\adhd-assessment-system\backend\mlmodels\it21288326\venv\Lib\site-packages\flask\app.py", line 917, in full_dispatch_request
    rv = self.dispatch_request()
         ^^^^^^^^^^^^^^^^^^^^^^^
  File "D:\research\adhd-assessment-system\backend\mlmodels\it21288326\venv\Lib\site-packages\flask\app.py", line 902, in dispatch_request
    return self.ensure_sync(self.view_functions[rule.endpoint])(**view_args)  # type: ignore[no-any-return]
           ^^^^^^^^^^^^^^^^^^^^^^^^^^^^^^^^^^^^^^^^^^^^^^^^^^^^^^^^^^^^^^^^^
  File "D:\research\adhd-assessment-system\backend\mlmodels\it21288326\retrain_model.py", line 2393, in get_model_config
    "timestamp": datetime.datetime.now().isoformat()
                 ^^^^^^^^^^^^^^^^^
AttributeError: type object 'datetime.datetime' has no attribute 'datetime'
2025-03-17 14:37:54,178 - werkzeug - INFO - 127.0.0.1 - - [17/Mar/2025 14:37:54] "[35m[1mGET /api/dashboard/model-config HTTP/1.1[0m" 500 -
2025-03-17 14:37:54,184 - werkzeug - INFO - 127.0.0.1 - - [17/Mar/2025 14:37:54] "GET /api/dashboard/system-status HTTP/1.1" 200 -
2025-03-17 14:37:54,855 - werkzeug - INFO - 127.0.0.1 - - [17/Mar/2025 14:37:54] "GET /api/dashboard/assessment-stats HTTP/1.1" 200 -
2025-03-17 14:37:54,857 - werkzeug - INFO - 127.0.0.1 - - [17/Mar/2025 14:37:54] "GET /api/dashboard/prediction-metrics HTTP/1.1" 200 -
2025-03-17 14:37:56,292 - werkzeug - INFO - 127.0.0.1 - - [17/Mar/2025 14:37:56] "GET /api/dashboard/assessment-stats HTTP/1.1" 200 -
2025-03-17 14:39:04,436 - __main__ - WARNING - Failed to retrieve dataset size: Collection objects do not implement truth value testing or bool(). Please compare with None instead: collection is not None
2025-03-17 14:39:04,453 - __main__ - ERROR - Error in calculate_performance_metrics_from_recent_data: Collection objects do not implement truth value testing or bool(). Please compare with None instead: collection is not None
2025-03-17 14:39:04,453 - werkzeug - INFO - 127.0.0.1 - - [17/Mar/2025 14:39:04] "GET /api/dashboard/model-metrics HTTP/1.1" 200 -
2025-03-17 14:39:04,453 - __main__ - INFO - No training_params.json file found, using default values
2025-03-17 14:39:04,453 - retrain_model - ERROR - Exception on /api/dashboard/model-config [GET]
Traceback (most recent call last):
  File "D:\research\adhd-assessment-system\backend\mlmodels\it21288326\venv\Lib\site-packages\flask\app.py", line 1511, in wsgi_app
    response = self.full_dispatch_request()
               ^^^^^^^^^^^^^^^^^^^^^^^^^^^^
  File "D:\research\adhd-assessment-system\backend\mlmodels\it21288326\venv\Lib\site-packages\flask\app.py", line 919, in full_dispatch_request
    rv = self.handle_user_exception(e)
         ^^^^^^^^^^^^^^^^^^^^^^^^^^^^^
  File "D:\research\adhd-assessment-system\backend\mlmodels\it21288326\venv\Lib\site-packages\flask_cors\extension.py", line 176, in wrapped_function
    return cors_after_request(app.make_response(f(*args, **kwargs)))
                                                ^^^^^^^^^^^^^^^^^^
  File "D:\research\adhd-assessment-system\backend\mlmodels\it21288326\venv\Lib\site-packages\flask\app.py", line 917, in full_dispatch_request
    rv = self.dispatch_request()
         ^^^^^^^^^^^^^^^^^^^^^^^
  File "D:\research\adhd-assessment-system\backend\mlmodels\it21288326\venv\Lib\site-packages\flask\app.py", line 902, in dispatch_request
    return self.ensure_sync(self.view_functions[rule.endpoint])(**view_args)  # type: ignore[no-any-return]
           ^^^^^^^^^^^^^^^^^^^^^^^^^^^^^^^^^^^^^^^^^^^^^^^^^^^^^^^^^^^^^^^^^
  File "D:\research\adhd-assessment-system\backend\mlmodels\it21288326\retrain_model.py", line 2393, in get_model_config
    "timestamp": datetime.datetime.now().isoformat()
                 ^^^^^^^^^^^^^^^^^
AttributeError: type object 'datetime.datetime' has no attribute 'datetime'
2025-03-17 14:39:04,476 - werkzeug - INFO - 127.0.0.1 - - [17/Mar/2025 14:39:04] "[35m[1mGET /api/dashboard/model-config HTTP/1.1[0m" 500 -
2025-03-17 14:39:04,611 - werkzeug - INFO - 127.0.0.1 - - [17/Mar/2025 14:39:04] "GET /api/dashboard/system-status HTTP/1.1" 200 -
2025-03-17 14:39:04,770 - werkzeug - INFO - 127.0.0.1 - - [17/Mar/2025 14:39:04] "GET /api/dashboard/prediction-metrics HTTP/1.1" 200 -
2025-03-17 14:39:05,362 - __main__ - WARNING - Failed to retrieve dataset size: Collection objects do not implement truth value testing or bool(). Please compare with None instead: collection is not None
2025-03-17 14:39:05,362 - __main__ - ERROR - Error in calculate_performance_metrics_from_recent_data: Collection objects do not implement truth value testing or bool(). Please compare with None instead: collection is not None
2025-03-17 14:39:05,362 - __main__ - INFO - No training_params.json file found, using default values
2025-03-17 14:39:05,387 - retrain_model - ERROR - Exception on /api/dashboard/model-config [GET]
Traceback (most recent call last):
  File "D:\research\adhd-assessment-system\backend\mlmodels\it21288326\venv\Lib\site-packages\flask\app.py", line 1511, in wsgi_app
    response = self.full_dispatch_request()
               ^^^^^^^^^^^^^^^^^^^^^^^^^^^^
  File "D:\research\adhd-assessment-system\backend\mlmodels\it21288326\venv\Lib\site-packages\flask\app.py", line 919, in full_dispatch_request
    rv = self.handle_user_exception(e)
         ^^^^^^^^^^^^^^^^^^^^^^^^^^^^^
  File "D:\research\adhd-assessment-system\backend\mlmodels\it21288326\venv\Lib\site-packages\flask_cors\extension.py", line 176, in wrapped_function
    return cors_after_request(app.make_response(f(*args, **kwargs)))
                                                ^^^^^^^^^^^^^^^^^^
  File "D:\research\adhd-assessment-system\backend\mlmodels\it21288326\venv\Lib\site-packages\flask\app.py", line 917, in full_dispatch_request
    rv = self.dispatch_request()
         ^^^^^^^^^^^^^^^^^^^^^^^
  File "D:\research\adhd-assessment-system\backend\mlmodels\it21288326\venv\Lib\site-packages\flask\app.py", line 902, in dispatch_request
    return self.ensure_sync(self.view_functions[rule.endpoint])(**view_args)  # type: ignore[no-any-return]
           ^^^^^^^^^^^^^^^^^^^^^^^^^^^^^^^^^^^^^^^^^^^^^^^^^^^^^^^^^^^^^^^^^
  File "D:\research\adhd-assessment-system\backend\mlmodels\it21288326\retrain_model.py", line 2393, in get_model_config
    "timestamp": datetime.datetime.now().isoformat()
                 ^^^^^^^^^^^^^^^^^
AttributeError: type object 'datetime.datetime' has no attribute 'datetime'
2025-03-17 14:39:05,387 - werkzeug - INFO - 127.0.0.1 - - [17/Mar/2025 14:39:05] "GET /api/dashboard/model-metrics HTTP/1.1" 200 -
2025-03-17 14:39:05,393 - werkzeug - INFO - 127.0.0.1 - - [17/Mar/2025 14:39:05] "[35m[1mGET /api/dashboard/model-config HTTP/1.1[0m" 500 -
2025-03-17 14:39:05,425 - werkzeug - INFO - 127.0.0.1 - - [17/Mar/2025 14:39:05] "GET /api/dashboard/system-status HTTP/1.1" 200 -
2025-03-17 14:39:05,701 - werkzeug - INFO - 127.0.0.1 - - [17/Mar/2025 14:39:05] "GET /api/dashboard/assessment-stats HTTP/1.1" 200 -
2025-03-17 14:39:05,714 - werkzeug - INFO - 127.0.0.1 - - [17/Mar/2025 14:39:05] "GET /api/dashboard/prediction-metrics HTTP/1.1" 200 -
2025-03-17 14:39:06,161 - __main__ - WARNING - Failed to retrieve dataset size: Collection objects do not implement truth value testing or bool(). Please compare with None instead: collection is not None
2025-03-17 14:39:06,170 - __main__ - ERROR - Error in calculate_performance_metrics_from_recent_data: Collection objects do not implement truth value testing or bool(). Please compare with None instead: collection is not None
2025-03-17 14:39:06,177 - __main__ - INFO - No training_params.json file found, using default values
2025-03-17 14:39:06,179 - werkzeug - INFO - 127.0.0.1 - - [17/Mar/2025 14:39:06] "GET /api/dashboard/model-metrics HTTP/1.1" 200 -
2025-03-17 14:39:06,181 - retrain_model - ERROR - Exception on /api/dashboard/model-config [GET]
Traceback (most recent call last):
  File "D:\research\adhd-assessment-system\backend\mlmodels\it21288326\venv\Lib\site-packages\flask\app.py", line 1511, in wsgi_app
    response = self.full_dispatch_request()
               ^^^^^^^^^^^^^^^^^^^^^^^^^^^^
  File "D:\research\adhd-assessment-system\backend\mlmodels\it21288326\venv\Lib\site-packages\flask\app.py", line 919, in full_dispatch_request
    rv = self.handle_user_exception(e)
         ^^^^^^^^^^^^^^^^^^^^^^^^^^^^^
  File "D:\research\adhd-assessment-system\backend\mlmodels\it21288326\venv\Lib\site-packages\flask_cors\extension.py", line 176, in wrapped_function
    return cors_after_request(app.make_response(f(*args, **kwargs)))
                                                ^^^^^^^^^^^^^^^^^^
  File "D:\research\adhd-assessment-system\backend\mlmodels\it21288326\venv\Lib\site-packages\flask\app.py", line 917, in full_dispatch_request
    rv = self.dispatch_request()
         ^^^^^^^^^^^^^^^^^^^^^^^
  File "D:\research\adhd-assessment-system\backend\mlmodels\it21288326\venv\Lib\site-packages\flask\app.py", line 902, in dispatch_request
    return self.ensure_sync(self.view_functions[rule.endpoint])(**view_args)  # type: ignore[no-any-return]
           ^^^^^^^^^^^^^^^^^^^^^^^^^^^^^^^^^^^^^^^^^^^^^^^^^^^^^^^^^^^^^^^^^
  File "D:\research\adhd-assessment-system\backend\mlmodels\it21288326\retrain_model.py", line 2393, in get_model_config
    "timestamp": datetime.datetime.now().isoformat()
                 ^^^^^^^^^^^^^^^^^
AttributeError: type object 'datetime.datetime' has no attribute 'datetime'
2025-03-17 14:39:06,183 - werkzeug - INFO - 127.0.0.1 - - [17/Mar/2025 14:39:06] "[35m[1mGET /api/dashboard/model-config HTTP/1.1[0m" 500 -
2025-03-17 14:39:06,411 - werkzeug - INFO - 127.0.0.1 - - [17/Mar/2025 14:39:06] "GET /api/dashboard/system-status HTTP/1.1" 200 -
2025-03-17 14:39:06,491 - __main__ - WARNING - Failed to retrieve dataset size: Collection objects do not implement truth value testing or bool(). Please compare with None instead: collection is not None
2025-03-17 14:39:06,497 - __main__ - ERROR - Error in calculate_performance_metrics_from_recent_data: Collection objects do not implement truth value testing or bool(). Please compare with None instead: collection is not None
2025-03-17 14:39:06,497 - werkzeug - INFO - 127.0.0.1 - - [17/Mar/2025 14:39:06] "GET /api/dashboard/model-metrics HTTP/1.1" 200 -
2025-03-17 14:39:06,507 - __main__ - INFO - No training_params.json file found, using default values
2025-03-17 14:39:06,509 - retrain_model - ERROR - Exception on /api/dashboard/model-config [GET]
Traceback (most recent call last):
  File "D:\research\adhd-assessment-system\backend\mlmodels\it21288326\venv\Lib\site-packages\flask\app.py", line 1511, in wsgi_app
    response = self.full_dispatch_request()
               ^^^^^^^^^^^^^^^^^^^^^^^^^^^^
  File "D:\research\adhd-assessment-system\backend\mlmodels\it21288326\venv\Lib\site-packages\flask\app.py", line 919, in full_dispatch_request
    rv = self.handle_user_exception(e)
         ^^^^^^^^^^^^^^^^^^^^^^^^^^^^^
  File "D:\research\adhd-assessment-system\backend\mlmodels\it21288326\venv\Lib\site-packages\flask_cors\extension.py", line 176, in wrapped_function
    return cors_after_request(app.make_response(f(*args, **kwargs)))
                                                ^^^^^^^^^^^^^^^^^^
  File "D:\research\adhd-assessment-system\backend\mlmodels\it21288326\venv\Lib\site-packages\flask\app.py", line 917, in full_dispatch_request
    rv = self.dispatch_request()
         ^^^^^^^^^^^^^^^^^^^^^^^
  File "D:\research\adhd-assessment-system\backend\mlmodels\it21288326\venv\Lib\site-packages\flask\app.py", line 902, in dispatch_request
    return self.ensure_sync(self.view_functions[rule.endpoint])(**view_args)  # type: ignore[no-any-return]
           ^^^^^^^^^^^^^^^^^^^^^^^^^^^^^^^^^^^^^^^^^^^^^^^^^^^^^^^^^^^^^^^^^
  File "D:\research\adhd-assessment-system\backend\mlmodels\it21288326\retrain_model.py", line 2393, in get_model_config
    "timestamp": datetime.datetime.now().isoformat()
                 ^^^^^^^^^^^^^^^^^
AttributeError: type object 'datetime.datetime' has no attribute 'datetime'
2025-03-17 14:39:06,515 - werkzeug - INFO - 127.0.0.1 - - [17/Mar/2025 14:39:06] "[35m[1mGET /api/dashboard/model-config HTTP/1.1[0m" 500 -
2025-03-17 14:39:06,613 - werkzeug - INFO - 127.0.0.1 - - [17/Mar/2025 14:39:06] "GET /api/dashboard/prediction-metrics HTTP/1.1" 200 -
2025-03-17 14:39:06,808 - __main__ - WARNING - Failed to retrieve dataset size: Collection objects do not implement truth value testing or bool(). Please compare with None instead: collection is not None
2025-03-17 14:39:06,808 - __main__ - ERROR - Error in calculate_performance_metrics_from_recent_data: Collection objects do not implement truth value testing or bool(). Please compare with None instead: collection is not None
2025-03-17 14:39:06,808 - werkzeug - INFO - 127.0.0.1 - - [17/Mar/2025 14:39:06] "GET /api/dashboard/model-metrics HTTP/1.1" 200 -
2025-03-17 14:39:06,827 - __main__ - INFO - No training_params.json file found, using default values
2025-03-17 14:39:06,827 - retrain_model - ERROR - Exception on /api/dashboard/model-config [GET]
Traceback (most recent call last):
  File "D:\research\adhd-assessment-system\backend\mlmodels\it21288326\venv\Lib\site-packages\flask\app.py", line 1511, in wsgi_app
    response = self.full_dispatch_request()
               ^^^^^^^^^^^^^^^^^^^^^^^^^^^^
  File "D:\research\adhd-assessment-system\backend\mlmodels\it21288326\venv\Lib\site-packages\flask\app.py", line 919, in full_dispatch_request
    rv = self.handle_user_exception(e)
         ^^^^^^^^^^^^^^^^^^^^^^^^^^^^^
  File "D:\research\adhd-assessment-system\backend\mlmodels\it21288326\venv\Lib\site-packages\flask_cors\extension.py", line 176, in wrapped_function
    return cors_after_request(app.make_response(f(*args, **kwargs)))
                                                ^^^^^^^^^^^^^^^^^^
  File "D:\research\adhd-assessment-system\backend\mlmodels\it21288326\venv\Lib\site-packages\flask\app.py", line 917, in full_dispatch_request
    rv = self.dispatch_request()
         ^^^^^^^^^^^^^^^^^^^^^^^
  File "D:\research\adhd-assessment-system\backend\mlmodels\it21288326\venv\Lib\site-packages\flask\app.py", line 902, in dispatch_request
    return self.ensure_sync(self.view_functions[rule.endpoint])(**view_args)  # type: ignore[no-any-return]
           ^^^^^^^^^^^^^^^^^^^^^^^^^^^^^^^^^^^^^^^^^^^^^^^^^^^^^^^^^^^^^^^^^
  File "D:\research\adhd-assessment-system\backend\mlmodels\it21288326\retrain_model.py", line 2393, in get_model_config
    "timestamp": datetime.datetime.now().isoformat()
                 ^^^^^^^^^^^^^^^^^
AttributeError: type object 'datetime.datetime' has no attribute 'datetime'
2025-03-17 14:39:06,834 - werkzeug - INFO - 127.0.0.1 - - [17/Mar/2025 14:39:06] "[35m[1mGET /api/dashboard/model-config HTTP/1.1[0m" 500 -
2025-03-17 14:39:06,927 - werkzeug - INFO - 127.0.0.1 - - [17/Mar/2025 14:39:06] "GET /api/dashboard/system-status HTTP/1.1" 200 -
2025-03-17 14:39:07,028 - werkzeug - INFO - 127.0.0.1 - - [17/Mar/2025 14:39:07] "GET /api/dashboard/assessment-stats HTTP/1.1" 200 -
2025-03-17 14:39:07,126 - __main__ - WARNING - Failed to retrieve dataset size: Collection objects do not implement truth value testing or bool(). Please compare with None instead: collection is not None
2025-03-17 14:39:07,126 - __main__ - ERROR - Error in calculate_performance_metrics_from_recent_data: Collection objects do not implement truth value testing or bool(). Please compare with None instead: collection is not None
2025-03-17 14:39:07,126 - werkzeug - INFO - 127.0.0.1 - - [17/Mar/2025 14:39:07] "GET /api/dashboard/model-metrics HTTP/1.1" 200 -
2025-03-17 14:39:07,147 - __main__ - INFO - No training_params.json file found, using default values
2025-03-17 14:39:07,147 - retrain_model - ERROR - Exception on /api/dashboard/model-config [GET]
Traceback (most recent call last):
  File "D:\research\adhd-assessment-system\backend\mlmodels\it21288326\venv\Lib\site-packages\flask\app.py", line 1511, in wsgi_app
    response = self.full_dispatch_request()
               ^^^^^^^^^^^^^^^^^^^^^^^^^^^^
  File "D:\research\adhd-assessment-system\backend\mlmodels\it21288326\venv\Lib\site-packages\flask\app.py", line 919, in full_dispatch_request
    rv = self.handle_user_exception(e)
         ^^^^^^^^^^^^^^^^^^^^^^^^^^^^^
  File "D:\research\adhd-assessment-system\backend\mlmodels\it21288326\venv\Lib\site-packages\flask_cors\extension.py", line 176, in wrapped_function
    return cors_after_request(app.make_response(f(*args, **kwargs)))
                                                ^^^^^^^^^^^^^^^^^^
  File "D:\research\adhd-assessment-system\backend\mlmodels\it21288326\venv\Lib\site-packages\flask\app.py", line 917, in full_dispatch_request
    rv = self.dispatch_request()
         ^^^^^^^^^^^^^^^^^^^^^^^
  File "D:\research\adhd-assessment-system\backend\mlmodels\it21288326\venv\Lib\site-packages\flask\app.py", line 902, in dispatch_request
    return self.ensure_sync(self.view_functions[rule.endpoint])(**view_args)  # type: ignore[no-any-return]
           ^^^^^^^^^^^^^^^^^^^^^^^^^^^^^^^^^^^^^^^^^^^^^^^^^^^^^^^^^^^^^^^^^
  File "D:\research\adhd-assessment-system\backend\mlmodels\it21288326\retrain_model.py", line 2393, in get_model_config
    "timestamp": datetime.datetime.now().isoformat()
                 ^^^^^^^^^^^^^^^^^
AttributeError: type object 'datetime.datetime' has no attribute 'datetime'
2025-03-17 14:39:07,147 - werkzeug - INFO - 127.0.0.1 - - [17/Mar/2025 14:39:07] "[35m[1mGET /api/dashboard/model-config HTTP/1.1[0m" 500 -
2025-03-17 14:39:07,222 - werkzeug - INFO - 127.0.0.1 - - [17/Mar/2025 14:39:07] "GET /api/dashboard/prediction-metrics HTTP/1.1" 200 -
2025-03-17 14:39:07,380 - werkzeug - INFO - 127.0.0.1 - - [17/Mar/2025 14:39:07] "GET /api/dashboard/system-status HTTP/1.1" 200 -
2025-03-17 14:39:07,444 - __main__ - WARNING - Failed to retrieve dataset size: Collection objects do not implement truth value testing or bool(). Please compare with None instead: collection is not None
2025-03-17 14:39:07,450 - __main__ - ERROR - Error in calculate_performance_metrics_from_recent_data: Collection objects do not implement truth value testing or bool(). Please compare with None instead: collection is not None
2025-03-17 14:39:07,453 - werkzeug - INFO - 127.0.0.1 - - [17/Mar/2025 14:39:07] "GET /api/dashboard/model-metrics HTTP/1.1" 200 -
2025-03-17 14:39:07,460 - __main__ - INFO - No training_params.json file found, using default values
2025-03-17 14:39:07,465 - retrain_model - ERROR - Exception on /api/dashboard/model-config [GET]
Traceback (most recent call last):
  File "D:\research\adhd-assessment-system\backend\mlmodels\it21288326\venv\Lib\site-packages\flask\app.py", line 1511, in wsgi_app
    response = self.full_dispatch_request()
               ^^^^^^^^^^^^^^^^^^^^^^^^^^^^
  File "D:\research\adhd-assessment-system\backend\mlmodels\it21288326\venv\Lib\site-packages\flask\app.py", line 919, in full_dispatch_request
    rv = self.handle_user_exception(e)
         ^^^^^^^^^^^^^^^^^^^^^^^^^^^^^
  File "D:\research\adhd-assessment-system\backend\mlmodels\it21288326\venv\Lib\site-packages\flask_cors\extension.py", line 176, in wrapped_function
    return cors_after_request(app.make_response(f(*args, **kwargs)))
                                                ^^^^^^^^^^^^^^^^^^
  File "D:\research\adhd-assessment-system\backend\mlmodels\it21288326\venv\Lib\site-packages\flask\app.py", line 917, in full_dispatch_request
    rv = self.dispatch_request()
         ^^^^^^^^^^^^^^^^^^^^^^^
  File "D:\research\adhd-assessment-system\backend\mlmodels\it21288326\venv\Lib\site-packages\flask\app.py", line 902, in dispatch_request
    return self.ensure_sync(self.view_functions[rule.endpoint])(**view_args)  # type: ignore[no-any-return]
           ^^^^^^^^^^^^^^^^^^^^^^^^^^^^^^^^^^^^^^^^^^^^^^^^^^^^^^^^^^^^^^^^^
  File "D:\research\adhd-assessment-system\backend\mlmodels\it21288326\retrain_model.py", line 2393, in get_model_config
    "timestamp": datetime.datetime.now().isoformat()
                 ^^^^^^^^^^^^^^^^^
AttributeError: type object 'datetime.datetime' has no attribute 'datetime'
2025-03-17 14:39:07,469 - werkzeug - INFO - 127.0.0.1 - - [17/Mar/2025 14:39:07] "[35m[1mGET /api/dashboard/model-config HTTP/1.1[0m" 500 -
2025-03-17 14:39:07,920 - werkzeug - INFO - 127.0.0.1 - - [17/Mar/2025 14:39:07] "GET /api/dashboard/prediction-metrics HTTP/1.1" 200 -
2025-03-17 14:39:07,956 - werkzeug - INFO - 127.0.0.1 - - [17/Mar/2025 14:39:07] "GET /api/dashboard/system-status HTTP/1.1" 200 -
2025-03-17 14:39:08,684 - werkzeug - INFO - 127.0.0.1 - - [17/Mar/2025 14:39:08] "GET /api/dashboard/assessment-stats HTTP/1.1" 200 -
2025-03-17 14:39:08,748 - werkzeug - INFO - 127.0.0.1 - - [17/Mar/2025 14:39:08] "GET /api/dashboard/system-status HTTP/1.1" 200 -
2025-03-17 14:39:08,827 - werkzeug - INFO - 127.0.0.1 - - [17/Mar/2025 14:39:08] "GET /api/dashboard/prediction-metrics HTTP/1.1" 200 -
2025-03-17 14:39:09,758 - werkzeug - INFO - 127.0.0.1 - - [17/Mar/2025 14:39:09] "GET /api/dashboard/prediction-metrics HTTP/1.1" 200 -
2025-03-17 14:39:10,201 - werkzeug - INFO - 127.0.0.1 - - [17/Mar/2025 14:39:10] "GET /api/dashboard/assessment-stats HTTP/1.1" 200 -
2025-03-17 14:39:11,633 - werkzeug - INFO - 127.0.0.1 - - [17/Mar/2025 14:39:11] "GET /api/dashboard/assessment-stats HTTP/1.1" 200 -
2025-03-17 14:39:13,184 - werkzeug - INFO - 127.0.0.1 - - [17/Mar/2025 14:39:13] "GET /api/dashboard/assessment-stats HTTP/1.1" 200 -
2025-03-17 14:39:14,825 - werkzeug - INFO - 127.0.0.1 - - [17/Mar/2025 14:39:14] "GET /api/dashboard/assessment-stats HTTP/1.1" 200 -
2025-03-17 14:40:38,654 - __main__ - WARNING - Failed to retrieve dataset size: Collection objects do not implement truth value testing or bool(). Please compare with None instead: collection is not None
2025-03-17 14:40:38,654 - __main__ - ERROR - Error in calculate_performance_metrics_from_recent_data: Collection objects do not implement truth value testing or bool(). Please compare with None instead: collection is not None
2025-03-17 14:40:38,670 - werkzeug - INFO - 127.0.0.1 - - [17/Mar/2025 14:40:38] "GET /api/dashboard/model-metrics HTTP/1.1" 200 -
2025-03-17 14:40:38,670 - __main__ - INFO - No training_params.json file found, using default values
2025-03-17 14:40:38,670 - retrain_model - ERROR - Exception on /api/dashboard/model-config [GET]
Traceback (most recent call last):
  File "D:\research\adhd-assessment-system\backend\mlmodels\it21288326\venv\Lib\site-packages\flask\app.py", line 1511, in wsgi_app
    response = self.full_dispatch_request()
               ^^^^^^^^^^^^^^^^^^^^^^^^^^^^
  File "D:\research\adhd-assessment-system\backend\mlmodels\it21288326\venv\Lib\site-packages\flask\app.py", line 919, in full_dispatch_request
    rv = self.handle_user_exception(e)
         ^^^^^^^^^^^^^^^^^^^^^^^^^^^^^
  File "D:\research\adhd-assessment-system\backend\mlmodels\it21288326\venv\Lib\site-packages\flask_cors\extension.py", line 176, in wrapped_function
    return cors_after_request(app.make_response(f(*args, **kwargs)))
                                                ^^^^^^^^^^^^^^^^^^
  File "D:\research\adhd-assessment-system\backend\mlmodels\it21288326\venv\Lib\site-packages\flask\app.py", line 917, in full_dispatch_request
    rv = self.dispatch_request()
         ^^^^^^^^^^^^^^^^^^^^^^^
  File "D:\research\adhd-assessment-system\backend\mlmodels\it21288326\venv\Lib\site-packages\flask\app.py", line 902, in dispatch_request
    return self.ensure_sync(self.view_functions[rule.endpoint])(**view_args)  # type: ignore[no-any-return]
           ^^^^^^^^^^^^^^^^^^^^^^^^^^^^^^^^^^^^^^^^^^^^^^^^^^^^^^^^^^^^^^^^^
  File "D:\research\adhd-assessment-system\backend\mlmodels\it21288326\retrain_model.py", line 2393, in get_model_config
    "timestamp": datetime.datetime.now().isoformat()
                 ^^^^^^^^^^^^^^^^^
AttributeError: type object 'datetime.datetime' has no attribute 'datetime'
2025-03-17 14:40:38,691 - werkzeug - INFO - 127.0.0.1 - - [17/Mar/2025 14:40:38] "[35m[1mGET /api/dashboard/model-config HTTP/1.1[0m" 500 -
2025-03-17 14:40:38,857 - werkzeug - INFO - 127.0.0.1 - - [17/Mar/2025 14:40:38] "GET /api/dashboard/system-status HTTP/1.1" 200 -
2025-03-17 14:40:38,893 - __main__ - WARNING - Failed to retrieve dataset size: Collection objects do not implement truth value testing or bool(). Please compare with None instead: collection is not None
2025-03-17 14:40:38,893 - __main__ - ERROR - Error in calculate_performance_metrics_from_recent_data: Collection objects do not implement truth value testing or bool(). Please compare with None instead: collection is not None
2025-03-17 14:40:38,893 - werkzeug - INFO - 127.0.0.1 - - [17/Mar/2025 14:40:38] "GET /api/dashboard/model-metrics HTTP/1.1" 200 -
2025-03-17 14:40:39,005 - __main__ - INFO - No training_params.json file found, using default values
2025-03-17 14:40:39,005 - retrain_model - ERROR - Exception on /api/dashboard/model-config [GET]
Traceback (most recent call last):
  File "D:\research\adhd-assessment-system\backend\mlmodels\it21288326\venv\Lib\site-packages\flask\app.py", line 1511, in wsgi_app
    response = self.full_dispatch_request()
               ^^^^^^^^^^^^^^^^^^^^^^^^^^^^
  File "D:\research\adhd-assessment-system\backend\mlmodels\it21288326\venv\Lib\site-packages\flask\app.py", line 919, in full_dispatch_request
    rv = self.handle_user_exception(e)
         ^^^^^^^^^^^^^^^^^^^^^^^^^^^^^
  File "D:\research\adhd-assessment-system\backend\mlmodels\it21288326\venv\Lib\site-packages\flask_cors\extension.py", line 176, in wrapped_function
    return cors_after_request(app.make_response(f(*args, **kwargs)))
                                                ^^^^^^^^^^^^^^^^^^
  File "D:\research\adhd-assessment-system\backend\mlmodels\it21288326\venv\Lib\site-packages\flask\app.py", line 917, in full_dispatch_request
    rv = self.dispatch_request()
         ^^^^^^^^^^^^^^^^^^^^^^^
  File "D:\research\adhd-assessment-system\backend\mlmodels\it21288326\venv\Lib\site-packages\flask\app.py", line 902, in dispatch_request
    return self.ensure_sync(self.view_functions[rule.endpoint])(**view_args)  # type: ignore[no-any-return]
           ^^^^^^^^^^^^^^^^^^^^^^^^^^^^^^^^^^^^^^^^^^^^^^^^^^^^^^^^^^^^^^^^^
  File "D:\research\adhd-assessment-system\backend\mlmodels\it21288326\retrain_model.py", line 2393, in get_model_config
    "timestamp": datetime.datetime.now().isoformat()
                 ^^^^^^^^^^^^^^^^^
AttributeError: type object 'datetime.datetime' has no attribute 'datetime'
2025-03-17 14:40:39,005 - werkzeug - INFO - 127.0.0.1 - - [17/Mar/2025 14:40:39] "[35m[1mGET /api/dashboard/model-config HTTP/1.1[0m" 500 -
2025-03-17 14:40:39,044 - werkzeug - INFO - 127.0.0.1 - - [17/Mar/2025 14:40:39] "GET /api/dashboard/prediction-metrics HTTP/1.1" 200 -
2025-03-17 14:40:39,381 - werkzeug - INFO - 127.0.0.1 - - [17/Mar/2025 14:40:39] "GET /api/dashboard/system-status HTTP/1.1" 200 -
2025-03-17 14:40:39,753 - werkzeug - INFO - 127.0.0.1 - - [17/Mar/2025 14:40:39] "GET /api/dashboard/assessment-stats HTTP/1.1" 200 -
2025-03-17 14:40:39,753 - werkzeug - INFO - 127.0.0.1 - - [17/Mar/2025 14:40:39] "GET /api/dashboard/prediction-metrics HTTP/1.1" 200 -
2025-03-17 14:40:41,401 - werkzeug - INFO - 127.0.0.1 - - [17/Mar/2025 14:40:41] "GET /api/dashboard/assessment-stats HTTP/1.1" 200 -
2025-03-17 14:41:10,483 - __main__ - INFO - MongoDB connection established successfully
2025-03-17 14:41:10,679 - __main__ - INFO - Model loaded successfully
2025-03-17 14:41:10,679 - __main__ - INFO - Scaler loaded successfully
2025-03-17 14:41:10,683 - __main__ - INFO - Label encoder loaded successfully
2025-03-17 14:41:10,686 - __main__ - INFO - Starting prediction service on http://localhost:5000
2025-03-17 14:41:10,691 - werkzeug - INFO - [31m[1mWARNING: This is a development server. Do not use it in a production deployment. Use a production WSGI server instead.[0m
 * Running on all addresses (0.0.0.0)
 * Running on http://127.0.0.1:5000
 * Running on http://172.28.4.140:5000
2025-03-17 14:41:10,699 - werkzeug - INFO - [33mPress CTRL+C to quit[0m
2025-03-17 14:41:22,135 - __main__ - WARNING - Failed to retrieve dataset size: Collection objects do not implement truth value testing or bool(). Please compare with None instead: collection is not None
2025-03-17 14:41:22,149 - __main__ - ERROR - Error in calculate_performance_metrics_from_recent_data: Collection objects do not implement truth value testing or bool(). Please compare with None instead: collection is not None
2025-03-17 14:41:22,149 - werkzeug - INFO - 127.0.0.1 - - [17/Mar/2025 14:41:22] "GET /api/dashboard/model-metrics HTTP/1.1" 200 -
2025-03-17 14:41:22,158 - __main__ - INFO - No training_params.json file found, using default values
2025-03-17 14:41:22,165 - retrain_model - ERROR - Exception on /api/dashboard/model-config [GET]
Traceback (most recent call last):
  File "D:\research\adhd-assessment-system\backend\mlmodels\it21288326\venv\Lib\site-packages\flask\app.py", line 1511, in wsgi_app
    response = self.full_dispatch_request()
               ^^^^^^^^^^^^^^^^^^^^^^^^^^^^
  File "D:\research\adhd-assessment-system\backend\mlmodels\it21288326\venv\Lib\site-packages\flask\app.py", line 919, in full_dispatch_request
    rv = self.handle_user_exception(e)
         ^^^^^^^^^^^^^^^^^^^^^^^^^^^^^
  File "D:\research\adhd-assessment-system\backend\mlmodels\it21288326\venv\Lib\site-packages\flask_cors\extension.py", line 176, in wrapped_function
    return cors_after_request(app.make_response(f(*args, **kwargs)))
                                                ^^^^^^^^^^^^^^^^^^
  File "D:\research\adhd-assessment-system\backend\mlmodels\it21288326\venv\Lib\site-packages\flask\app.py", line 917, in full_dispatch_request
    rv = self.dispatch_request()
         ^^^^^^^^^^^^^^^^^^^^^^^
  File "D:\research\adhd-assessment-system\backend\mlmodels\it21288326\venv\Lib\site-packages\flask\app.py", line 902, in dispatch_request
    return self.ensure_sync(self.view_functions[rule.endpoint])(**view_args)  # type: ignore[no-any-return]
           ^^^^^^^^^^^^^^^^^^^^^^^^^^^^^^^^^^^^^^^^^^^^^^^^^^^^^^^^^^^^^^^^^
  File "D:\research\adhd-assessment-system\backend\mlmodels\it21288326\retrain_model.py", line 2393, in get_model_config
    "timestamp": datetime.datetime.now().isoformat()
                 ^^^^^^^^^^^^^^^^^
AttributeError: type object 'datetime.datetime' has no attribute 'datetime'
2025-03-17 14:41:22,180 - werkzeug - INFO - 127.0.0.1 - - [17/Mar/2025 14:41:22] "[35m[1mGET /api/dashboard/model-config HTTP/1.1[0m" 500 -
2025-03-17 14:41:22,539 - werkzeug - INFO - 127.0.0.1 - - [17/Mar/2025 14:41:22] "GET /api/dashboard/system-status HTTP/1.1" 200 -
2025-03-17 14:41:24,106 - werkzeug - INFO - 127.0.0.1 - - [17/Mar/2025 14:41:24] "GET /api/dashboard/prediction-metrics HTTP/1.1" 200 -
2025-03-17 14:41:24,632 - werkzeug - INFO - 127.0.0.1 - - [17/Mar/2025 14:41:24] "GET /api/dashboard/assessment-stats HTTP/1.1" 200 -
2025-03-17 15:06:13,425 - __main__ - INFO - MongoDB connection established successfully
2025-03-17 15:06:13,808 - __main__ - INFO - Model loaded successfully
2025-03-17 15:06:13,808 - __main__ - INFO - Scaler loaded successfully
2025-03-17 15:06:13,808 - __main__ - INFO - Label encoder loaded successfully
2025-03-17 15:06:13,821 - __main__ - INFO - Starting prediction service on http://localhost:5000
2025-03-17 15:06:13,844 - werkzeug - INFO - [31m[1mWARNING: This is a development server. Do not use it in a production deployment. Use a production WSGI server instead.[0m
 * Running on all addresses (0.0.0.0)
 * Running on http://127.0.0.1:5000
 * Running on http://172.28.4.140:5000
2025-03-17 15:06:13,844 - werkzeug - INFO - [33mPress CTRL+C to quit[0m
2025-03-17 15:09:19,387 - werkzeug - INFO - 127.0.0.1 - - [17/Mar/2025 15:09:19] "GET /health HTTP/1.1" 200 -
2025-03-17 15:09:19,623 - werkzeug - INFO - 127.0.0.1 - - [17/Mar/2025 15:09:19] "GET /health HTTP/1.1" 200 -
2025-03-17 15:14:20,579 - werkzeug - INFO - 127.0.0.1 - - [17/Mar/2025 15:14:20] "GET /health HTTP/1.1" 200 -
2025-03-17 15:19:20,289 - werkzeug - INFO - 127.0.0.1 - - [17/Mar/2025 15:19:20] "GET /health HTTP/1.1" 200 -
2025-03-17 15:24:22,171 - werkzeug - INFO - 127.0.0.1 - - [17/Mar/2025 15:24:22] "GET /health HTTP/1.1" 200 -
2025-03-17 15:29:51,535 - werkzeug - INFO - 127.0.0.1 - - [17/Mar/2025 15:29:51] "GET /health HTTP/1.1" 200 -
2025-03-17 15:42:00,232 - __main__ - INFO - MongoDB connection established successfully
2025-03-17 15:42:00,545 - __main__ - INFO - Model loaded successfully
2025-03-17 15:42:00,576 - __main__ - INFO - Scaler loaded successfully
2025-03-17 15:42:00,599 - __main__ - INFO - Label encoder loaded successfully
2025-03-17 15:42:00,603 - __main__ - INFO - Starting prediction service on http://localhost:5000
2025-03-17 15:42:00,648 - werkzeug - INFO - [31m[1mWARNING: This is a development server. Do not use it in a production deployment. Use a production WSGI server instead.[0m
 * Running on all addresses (0.0.0.0)
 * Running on http://127.0.0.1:5000
 * Running on http://172.28.4.140:5000
2025-03-17 15:42:00,648 - werkzeug - INFO - [33mPress CTRL+C to quit[0m
2025-03-17 16:32:22,003 - werkzeug - INFO - 127.0.0.1 - - [17/Mar/2025 16:32:22] "OPTIONS /predict HTTP/1.1" 200 -
2025-03-17 16:32:22,019 - werkzeug - INFO - 127.0.0.1 - - [17/Mar/2025 16:32:21] "OPTIONS /predict HTTP/1.1" 200 -
2025-03-17 16:32:22,022 - werkzeug - INFO - 127.0.0.1 - - [17/Mar/2025 16:32:22] "OPTIONS /predict HTTP/1.1" 200 -
2025-03-17 16:32:23,499 - __main__ - INFO - Model loaded successfully
2025-03-17 16:32:23,499 - __main__ - INFO - Model loaded successfully
2025-03-17 16:32:23,515 - __main__ - INFO - Model loaded successfully
2025-03-17 16:32:23,515 - __main__ - INFO - Scaler loaded successfully
2025-03-17 16:32:23,515 - __main__ - INFO - Scaler loaded successfully
2025-03-17 16:32:23,524 - __main__ - INFO - Scaler loaded successfully
2025-03-17 16:32:23,531 - __main__ - INFO - Label encoder loaded successfully
2025-03-17 16:32:23,531 - __main__ - INFO - Label encoder loaded successfully
2025-03-17 16:32:23,547 - __main__ - INFO - Label encoder loaded successfully
2025-03-17 16:32:25,360 - __main__ - INFO - Successfully processed prediction for game data
2025-03-17 16:32:25,360 - werkzeug - INFO - 127.0.0.1 - - [17/Mar/2025 16:32:25] "POST /predict HTTP/1.1" 200 -
2025-03-17 16:32:25,360 - __main__ - INFO - Successfully processed prediction for game data
2025-03-17 16:32:25,376 - werkzeug - INFO - 127.0.0.1 - - [17/Mar/2025 16:32:25] "POST /predict HTTP/1.1" 200 -
2025-03-17 16:32:25,376 - __main__ - INFO - Successfully processed prediction for game data
2025-03-17 16:32:25,376 - werkzeug - INFO - 127.0.0.1 - - [17/Mar/2025 16:32:25] "POST /predict HTTP/1.1" 200 -
2025-03-17 16:34:02,313 - werkzeug - INFO - 127.0.0.1 - - [17/Mar/2025 16:34:02] "OPTIONS /predict HTTP/1.1" 200 -
2025-03-17 16:34:02,726 - __main__ - INFO - Model loaded successfully
2025-03-17 16:34:02,730 - __main__ - INFO - Scaler loaded successfully
2025-03-17 16:34:02,732 - __main__ - INFO - Label encoder loaded successfully
2025-03-17 16:34:02,948 - __main__ - INFO - Successfully processed prediction for game data
2025-03-17 16:34:02,948 - werkzeug - INFO - 127.0.0.1 - - [17/Mar/2025 16:34:02] "POST /predict HTTP/1.1" 200 -
2025-03-17 16:34:20,885 - werkzeug - INFO - 127.0.0.1 - - [17/Mar/2025 16:34:20] "OPTIONS /predict HTTP/1.1" 200 -
2025-03-17 16:34:21,201 - werkzeug - INFO - 127.0.0.1 - - [17/Mar/2025 16:34:21] "OPTIONS /predict HTTP/1.1" 200 -
2025-03-17 16:34:21,283 - __main__ - INFO - Model loaded successfully
2025-03-17 16:34:21,283 - __main__ - INFO - Scaler loaded successfully
2025-03-17 16:34:21,283 - __main__ - INFO - Label encoder loaded successfully
2025-03-17 16:34:21,435 - tensorflow - WARNING - 5 out of the last 5 calls to <function TensorFlowTrainer.make_predict_function.<locals>.one_step_on_data_distributed at 0x0000020A114DA700> triggered tf.function retracing. Tracing is expensive and the excessive number of tracings could be due to (1) creating @tf.function repeatedly in a loop, (2) passing tensors with different shapes, (3) passing Python objects instead of tensors. For (1), please define your @tf.function outside of the loop. For (2), @tf.function has reduce_retracing=True option that can avoid unnecessary retracing. For (3), please refer to https://www.tensorflow.org/guide/function#controlling_retracing and https://www.tensorflow.org/api_docs/python/tf/function for  more details.
2025-03-17 16:34:21,485 - __main__ - INFO - Successfully processed prediction for game data
2025-03-17 16:34:21,485 - werkzeug - INFO - 127.0.0.1 - - [17/Mar/2025 16:34:21] "POST /predict HTTP/1.1" 200 -
2025-03-17 16:34:21,594 - __main__ - INFO - Model loaded successfully
2025-03-17 16:34:21,594 - __main__ - INFO - Scaler loaded successfully
2025-03-17 16:34:21,594 - __main__ - INFO - Label encoder loaded successfully
2025-03-17 16:34:21,696 - tensorflow - WARNING - 6 out of the last 6 calls to <function TensorFlowTrainer.make_predict_function.<locals>.one_step_on_data_distributed at 0x0000020A114A3BA0> triggered tf.function retracing. Tracing is expensive and the excessive number of tracings could be due to (1) creating @tf.function repeatedly in a loop, (2) passing tensors with different shapes, (3) passing Python objects instead of tensors. For (1), please define your @tf.function outside of the loop. For (2), @tf.function has reduce_retracing=True option that can avoid unnecessary retracing. For (3), please refer to https://www.tensorflow.org/guide/function#controlling_retracing and https://www.tensorflow.org/api_docs/python/tf/function for  more details.
2025-03-17 16:34:21,735 - __main__ - INFO - Successfully processed prediction for game data
2025-03-17 16:34:21,735 - werkzeug - INFO - 127.0.0.1 - - [17/Mar/2025 16:34:21] "POST /predict HTTP/1.1" 200 -
2025-03-17 16:34:28,223 - werkzeug - INFO - 127.0.0.1 - - [17/Mar/2025 16:34:28] "OPTIONS /predict HTTP/1.1" 200 -
2025-03-17 16:34:28,232 - werkzeug - INFO - 127.0.0.1 - - [17/Mar/2025 16:34:28] "OPTIONS /predict HTTP/1.1" 200 -
2025-03-17 16:34:28,609 - __main__ - INFO - Model loaded successfully
2025-03-17 16:34:28,623 - __main__ - INFO - Scaler loaded successfully
2025-03-17 16:34:28,638 - __main__ - INFO - Label encoder loaded successfully
2025-03-17 16:34:28,732 - __main__ - INFO - Model loaded successfully
2025-03-17 16:34:28,732 - __main__ - INFO - Scaler loaded successfully
2025-03-17 16:34:28,732 - __main__ - INFO - Label encoder loaded successfully
2025-03-17 16:34:28,856 - __main__ - INFO - Successfully processed prediction for game data
2025-03-17 16:34:28,856 - werkzeug - INFO - 127.0.0.1 - - [17/Mar/2025 16:34:28] "POST /predict HTTP/1.1" 200 -
2025-03-17 16:34:28,935 - __main__ - INFO - Successfully processed prediction for game data
2025-03-17 16:34:28,944 - werkzeug - INFO - 127.0.0.1 - - [17/Mar/2025 16:34:28] "POST /predict HTTP/1.1" 200 -
2025-03-17 16:35:07,882 - werkzeug - INFO - 127.0.0.1 - - [17/Mar/2025 16:35:07] "OPTIONS /predict HTTP/1.1" 200 -
2025-03-17 16:35:08,374 - __main__ - INFO - Model loaded successfully
2025-03-17 16:35:08,374 - __main__ - INFO - Scaler loaded successfully
2025-03-17 16:35:08,382 - __main__ - INFO - Label encoder loaded successfully
2025-03-17 16:35:08,543 - __main__ - INFO - Successfully processed prediction for game data
2025-03-17 16:35:08,543 - werkzeug - INFO - 127.0.0.1 - - [17/Mar/2025 16:35:08] "POST /predict HTTP/1.1" 200 -
2025-03-17 16:35:27,892 - werkzeug - INFO - 127.0.0.1 - - [17/Mar/2025 16:35:27] "OPTIONS /predict HTTP/1.1" 200 -
2025-03-17 16:35:28,292 - __main__ - INFO - Model loaded successfully
2025-03-17 16:35:28,293 - __main__ - INFO - Scaler loaded successfully
2025-03-17 16:35:28,294 - __main__ - INFO - Label encoder loaded successfully
2025-03-17 16:35:28,425 - __main__ - INFO - Successfully processed prediction for game data
2025-03-17 16:35:28,425 - werkzeug - INFO - 127.0.0.1 - - [17/Mar/2025 16:35:28] "POST /predict HTTP/1.1" 200 -
2025-03-17 16:36:46,659 - werkzeug - INFO - 127.0.0.1 - - [17/Mar/2025 16:36:46] "OPTIONS /predict HTTP/1.1" 200 -
2025-03-17 16:36:46,659 - werkzeug - INFO - 127.0.0.1 - - [17/Mar/2025 16:36:46] "OPTIONS /predict HTTP/1.1" 200 -
2025-03-17 16:36:46,899 - werkzeug - INFO - 127.0.0.1 - - [17/Mar/2025 16:36:46] "OPTIONS /predict HTTP/1.1" 200 -
2025-03-17 16:36:47,597 - __main__ - INFO - Model loaded successfully
2025-03-17 16:36:47,613 - __main__ - INFO - Scaler loaded successfully
2025-03-17 16:36:47,629 - __main__ - INFO - Label encoder loaded successfully
2025-03-17 16:36:47,808 - __main__ - INFO - Model loaded successfully
2025-03-17 16:36:47,820 - __main__ - INFO - Scaler loaded successfully
2025-03-17 16:36:47,837 - __main__ - INFO - Label encoder loaded successfully
2025-03-17 16:36:47,869 - __main__ - INFO - Model loaded successfully
2025-03-17 16:36:47,885 - __main__ - INFO - Scaler loaded successfully
2025-03-17 16:36:47,885 - __main__ - INFO - Label encoder loaded successfully
2025-03-17 16:36:48,267 - __main__ - INFO - Successfully processed prediction for game data
2025-03-17 16:36:48,283 - werkzeug - INFO - 127.0.0.1 - - [17/Mar/2025 16:36:48] "POST /predict HTTP/1.1" 200 -
2025-03-17 16:36:48,444 - __main__ - INFO - Successfully processed prediction for game data
2025-03-17 16:36:48,444 - werkzeug - INFO - 127.0.0.1 - - [17/Mar/2025 16:36:48] "POST /predict HTTP/1.1" 200 -
2025-03-17 16:36:48,496 - __main__ - INFO - Successfully processed prediction for game data
2025-03-17 16:36:48,498 - werkzeug - INFO - 127.0.0.1 - - [17/Mar/2025 16:36:48] "POST /predict HTTP/1.1" 200 -
2025-03-28 09:19:20,550 - __main__ - INFO - MongoDB connection established successfully
2025-03-28 09:19:20,672 - __main__ - ERROR - Error loading model from D:/research/adhd-assessment-system/backend/mlmodels/it21288326/venv/adhd_model.keras: File not found: filepath=D:/research/adhd-assessment-system/backend/mlmodels/it21288326/venv/adhd_model.keras. Please ensure the file is an accessible `.keras` zip file.
2025-03-28 09:19:20,672 - __main__ - ERROR - Error loading model from fallback location: File not found: filepath=adhd_model_fallback.keras. Please ensure the file is an accessible `.keras` zip file.
2025-03-28 09:19:20,672 - __main__ - ERROR - Error: Could not load model. Please train the model first.
2025-03-28 09:19:20,684 - __main__ - INFO - Starting prediction service on http://localhost:5000
2025-03-28 09:19:20,709 - werkzeug - INFO - [31m[1mWARNING: This is a development server. Do not use it in a production deployment. Use a production WSGI server instead.[0m
 * Running on all addresses (0.0.0.0)
 * Running on http://127.0.0.1:5000
 * Running on http://192.168.8.137:5000
2025-03-28 09:19:20,709 - werkzeug - INFO - [33mPress CTRL+C to quit[0m
2025-03-28 09:19:32,627 - werkzeug - INFO - 127.0.0.1 - - [28/Mar/2025 09:19:32] "GET /health HTTP/1.1" 200 -
2025-03-28 09:19:33,042 - werkzeug - INFO - 127.0.0.1 - - [28/Mar/2025 09:19:33] "GET /health HTTP/1.1" 200 -
2025-03-28 09:24:33,485 - werkzeug - INFO - 127.0.0.1 - - [28/Mar/2025 09:24:33] "GET /health HTTP/1.1" 200 -
2025-03-28 09:29:33,522 - werkzeug - INFO - 127.0.0.1 - - [28/Mar/2025 09:29:33] "GET /health HTTP/1.1" 200 -
2025-03-28 09:34:33,546 - werkzeug - INFO - 127.0.0.1 - - [28/Mar/2025 09:34:33] "GET /health HTTP/1.1" 200 -
2025-03-28 09:39:33,421 - werkzeug - INFO - 127.0.0.1 - - [28/Mar/2025 09:39:33] "GET /health HTTP/1.1" 200 -
2025-03-28 09:44:19,886 - werkzeug - INFO - 127.0.0.1 - - [28/Mar/2025 09:44:19] "GET /health HTTP/1.1" 200 -
2025-03-28 09:44:32,194 - werkzeug - INFO - 127.0.0.1 - - [28/Mar/2025 09:44:32] "GET /health HTTP/1.1" 200 -
2025-03-28 09:50:01,935 - werkzeug - INFO - 127.0.0.1 - - [28/Mar/2025 09:50:01] "GET /health HTTP/1.1" 200 -
2025-03-28 09:55:01,356 - werkzeug - INFO - 127.0.0.1 - - [28/Mar/2025 09:55:01] "GET /health HTTP/1.1" 200 -
2025-03-28 10:00:01,575 - werkzeug - INFO - 127.0.0.1 - - [28/Mar/2025 10:00:01] "GET /health HTTP/1.1" 200 -
2025-03-28 10:11:50,694 - werkzeug - INFO - 127.0.0.1 - - [28/Mar/2025 10:11:50] "GET /health HTTP/1.1" 200 -
2025-03-28 10:15:02,148 - werkzeug - INFO - 127.0.0.1 - - [28/Mar/2025 10:15:02] "GET /health HTTP/1.1" 200 -
2025-03-28 10:20:01,324 - werkzeug - INFO - 127.0.0.1 - - [28/Mar/2025 10:20:01] "GET /health HTTP/1.1" 200 -
2025-03-28 10:25:01,421 - werkzeug - INFO - 127.0.0.1 - - [28/Mar/2025 10:25:01] "GET /health HTTP/1.1" 200 -
2025-03-28 10:30:01,433 - werkzeug - INFO - 127.0.0.1 - - [28/Mar/2025 10:30:01] "GET /health HTTP/1.1" 200 -
2025-03-28 10:35:01,460 - werkzeug - INFO - 127.0.0.1 - - [28/Mar/2025 10:35:01] "GET /health HTTP/1.1" 200 -
2025-03-28 10:40:01,494 - werkzeug - INFO - 127.0.0.1 - - [28/Mar/2025 10:40:01] "GET /health HTTP/1.1" 200 -
2025-03-28 10:45:01,347 - werkzeug - INFO - 127.0.0.1 - - [28/Mar/2025 10:45:01] "GET /health HTTP/1.1" 200 -
2025-03-28 10:46:31,653 - __main__ - INFO - MongoDB connection established successfully
2025-03-28 10:46:33,286 - __main__ - ERROR - Error loading model from D:/research/adhd-assessment-system/backend/mlmodels/it21288326/venv/adhd_model.keras: File not found: filepath=D:/research/adhd-assessment-system/backend/mlmodels/it21288326/venv/adhd_model.keras. Please ensure the file is an accessible `.keras` zip file.
2025-03-28 10:46:33,323 - __main__ - ERROR - Error loading model from fallback location: File not found: filepath=adhd_model_fallback.keras. Please ensure the file is an accessible `.keras` zip file.
2025-03-28 10:46:33,324 - __main__ - ERROR - Error: Could not load model. Please train the model first.
2025-03-28 10:46:33,328 - __main__ - INFO - Starting prediction service on http://localhost:5000
2025-03-28 10:46:33,413 - werkzeug - INFO - [31m[1mWARNING: This is a development server. Do not use it in a production deployment. Use a production WSGI server instead.[0m
 * Running on all addresses (0.0.0.0)
 * Running on http://127.0.0.1:5000
 * Running on http://192.168.8.137:5000
2025-03-28 10:46:33,416 - werkzeug - INFO - [33mPress CTRL+C to quit[0m
2025-03-28 10:48:42,740 - __main__ - INFO - MongoDB connection established successfully
2025-03-28 10:48:42,768 - __main__ - ERROR - Error loading model from D:/research/adhd-assessment-system/backend/mlmodels/it21288326/venv/adhd_model.keras: File not found: filepath=D:/research/adhd-assessment-system/backend/mlmodels/it21288326/venv/adhd_model.keras. Please ensure the file is an accessible `.keras` zip file.
2025-03-28 10:48:42,772 - __main__ - ERROR - Error loading model from fallback location: File not found: filepath=adhd_model_fallback.keras. Please ensure the file is an accessible `.keras` zip file.
2025-03-28 10:48:42,776 - __main__ - ERROR - Error: Could not load model. Please train the model first.
2025-03-28 10:48:42,779 - __main__ - INFO - Starting prediction service on http://localhost:5000
2025-03-28 10:48:42,788 - werkzeug - INFO - [31m[1mWARNING: This is a development server. Do not use it in a production deployment. Use a production WSGI server instead.[0m
 * Running on all addresses (0.0.0.0)
 * Running on http://127.0.0.1:5000
 * Running on http://192.168.8.137:5000
2025-03-28 10:48:42,791 - werkzeug - INFO - [33mPress CTRL+C to quit[0m
2025-03-28 10:52:34,050 - __main__ - INFO - MongoDB connection established successfully
2025-03-28 10:52:36,045 - __main__ - INFO - Model loaded successfully
2025-03-28 10:52:36,124 - __main__ - INFO - Scaler loaded successfully
2025-03-28 10:52:36,158 - __main__ - INFO - Label encoder loaded successfully
2025-03-28 10:52:36,176 - __main__ - INFO - Starting prediction service on http://localhost:5000
2025-03-28 10:52:36,187 - werkzeug - INFO - [31m[1mWARNING: This is a development server. Do not use it in a production deployment. Use a production WSGI server instead.[0m
 * Running on all addresses (0.0.0.0)
 * Running on http://127.0.0.1:5000
 * Running on http://192.168.8.137:5000
2025-03-28 10:52:36,189 - werkzeug - INFO - [33mPress CTRL+C to quit[0m
2025-03-28 10:53:00,778 - werkzeug - INFO - 127.0.0.1 - - [28/Mar/2025 10:53:00] "GET /health HTTP/1.1" 200 -
2025-03-28 10:53:01,490 - werkzeug - INFO - 127.0.0.1 - - [28/Mar/2025 10:53:01] "GET /health HTTP/1.1" 200 -
2025-03-28 10:55:54,490 - __main__ - INFO - MongoDB connection established successfully
2025-03-28 10:55:54,688 - __main__ - INFO - Model loaded successfully
2025-03-28 10:55:54,691 - __main__ - INFO - Scaler loaded successfully
2025-03-28 10:55:54,691 - __main__ - INFO - Label encoder loaded successfully
2025-03-28 10:55:54,691 - __main__ - INFO - Starting prediction service on http://localhost:5000
2025-03-28 10:55:54,707 - werkzeug - INFO - [31m[1mWARNING: This is a development server. Do not use it in a production deployment. Use a production WSGI server instead.[0m
 * Running on all addresses (0.0.0.0)
 * Running on http://127.0.0.1:5000
 * Running on http://192.168.8.137:5000
2025-03-28 10:55:54,709 - werkzeug - INFO - [33mPress CTRL+C to quit[0m
2025-03-28 10:58:01,328 - werkzeug - INFO - 127.0.0.1 - - [28/Mar/2025 10:58:01] "GET /health HTTP/1.1" 200 -
2025-03-28 11:03:01,330 - werkzeug - INFO - 127.0.0.1 - - [28/Mar/2025 11:03:01] "GET /health HTTP/1.1" 200 -
2025-03-28 11:08:01,515 - werkzeug - INFO - 127.0.0.1 - - [28/Mar/2025 11:08:01] "GET /health HTTP/1.1" 200 -
2025-03-28 11:13:01,325 - werkzeug - INFO - 127.0.0.1 - - [28/Mar/2025 11:13:01] "GET /health HTTP/1.1" 200 -
2025-03-28 11:18:01,331 - werkzeug - INFO - 127.0.0.1 - - [28/Mar/2025 11:18:01] "GET /health HTTP/1.1" 200 -
2025-03-28 11:23:01,387 - werkzeug - INFO - 127.0.0.1 - - [28/Mar/2025 11:23:01] "GET /health HTTP/1.1" 200 -
2025-03-28 11:28:12,668 - werkzeug - INFO - 127.0.0.1 - - [28/Mar/2025 11:28:12] "GET /health HTTP/1.1" 200 -
2025-03-28 11:33:02,902 - werkzeug - INFO - 127.0.0.1 - - [28/Mar/2025 11:33:02] "GET /health HTTP/1.1" 200 -
2025-03-28 12:45:50,624 - werkzeug - INFO - 127.0.0.1 - - [28/Mar/2025 12:45:50] "OPTIONS /predict HTTP/1.1" 200 -
2025-03-28 12:45:50,624 - werkzeug - INFO - 127.0.0.1 - - [28/Mar/2025 12:45:50] "OPTIONS /predict HTTP/1.1" 200 -
2025-03-28 12:45:50,624 - werkzeug - INFO - 127.0.0.1 - - [28/Mar/2025 12:45:50] "OPTIONS /predict HTTP/1.1" 200 -
2025-03-28 12:46:03,492 - __main__ - INFO - Model loaded successfully
2025-03-28 12:46:03,503 - __main__ - INFO - Model loaded successfully
2025-03-28 12:46:03,470 - __main__ - INFO - Model loaded successfully
2025-03-28 12:46:03,665 - __main__ - INFO - Scaler loaded successfully
2025-03-28 12:46:03,665 - __main__ - INFO - Scaler loaded successfully
2025-03-28 12:46:03,665 - __main__ - INFO - Scaler loaded successfully
2025-03-28 12:46:03,709 - __main__ - INFO - Label encoder loaded successfully
2025-03-28 12:46:03,709 - __main__ - INFO - Label encoder loaded successfully
2025-03-28 12:46:03,709 - __main__ - INFO - Label encoder loaded successfully
2025-03-28 12:46:23,377 - __main__ - INFO - Successfully processed prediction for game data
2025-03-28 12:46:23,378 - __main__ - INFO - Successfully processed prediction for game data
2025-03-28 12:46:23,378 - __main__ - INFO - Successfully processed prediction for game data
2025-03-28 12:46:23,413 - werkzeug - INFO - 127.0.0.1 - - [28/Mar/2025 12:46:23] "POST /predict HTTP/1.1" 200 -
2025-03-28 12:46:23,415 - werkzeug - INFO - 127.0.0.1 - - [28/Mar/2025 12:46:23] "POST /predict HTTP/1.1" 200 -
2025-03-28 12:46:23,416 - werkzeug - INFO - 127.0.0.1 - - [28/Mar/2025 12:46:23] "POST /predict HTTP/1.1" 200 -
2025-03-28 13:57:25,913 - werkzeug - INFO - 127.0.0.1 - - [28/Mar/2025 13:57:25] "GET /health HTTP/1.1" 200 -
2025-03-28 13:57:26,049 - werkzeug - INFO - 127.0.0.1 - - [28/Mar/2025 13:57:26] "GET /health HTTP/1.1" 200 -
2025-03-28 13:57:49,537 - werkzeug - INFO - 127.0.0.1 - - [28/Mar/2025 13:57:49] "OPTIONS /retrain HTTP/1.1" 200 -
2025-03-28 13:57:49,917 - werkzeug - INFO - 127.0.0.1 - - [28/Mar/2025 13:57:49] "[31m[1mPOST /retrain HTTP/1.1[0m" 401 -
2025-03-28 13:58:49,129 - werkzeug - INFO - 127.0.0.1 - - [28/Mar/2025 13:58:49] "GET /health HTTP/1.1" 200 -
2025-03-28 14:00:21,422 - werkzeug - INFO - 127.0.0.1 - - [28/Mar/2025 14:00:21] "GET /health HTTP/1.1" 200 -
2025-03-28 14:00:24,206 - werkzeug - INFO - 127.0.0.1 - - [28/Mar/2025 14:00:24] "OPTIONS /retrain HTTP/1.1" 200 -
2025-03-28 14:00:30,748 - __main__ - INFO - Loaded 200 records from CSV.
2025-03-28 14:01:03,888 - __main__ - INFO - Total dataset size: 200 records
2025-03-28 14:01:05,167 - __main__ - ERROR - Error in prepare_features: Missing features in data: ['maxMissedStreak']
Traceback (most recent call last):
  File "E:\New folder (2)\adhd-assessment-system\backend\mlmodels\it21288326\retrain_model.py", line 1192, in prepare_features
    raise DataError(f"Missing features in data: {missing_features}")
DataError: Missing features in data: ['maxMissedStreak']

2025-03-28 14:01:05,177 - __main__ - ERROR - Error in train_model: Feature preparation failed: Missing features in data: ['maxMissedStreak']
Traceback (most recent call last):
  File "E:\New folder (2)\adhd-assessment-system\backend\mlmodels\it21288326\retrain_model.py", line 1192, in prepare_features
    raise DataError(f"Missing features in data: {missing_features}")
DataError: Missing features in data: ['maxMissedStreak']

During handling of the above exception, another exception occurred:

Traceback (most recent call last):
  File "E:\New folder (2)\adhd-assessment-system\backend\mlmodels\it21288326\retrain_model.py", line 1219, in train_model
    X_scaled, scaler, feature_columns = prepare_features(data)
                                        ^^^^^^^^^^^^^^^^^^^^^^
  File "E:\New folder (2)\adhd-assessment-system\backend\mlmodels\it21288326\retrain_model.py", line 1207, in prepare_features
    raise DataError(f"Feature preparation failed: {str(e)}")
DataError: Feature preparation failed: Missing features in data: ['maxMissedStreak']

2025-03-28 14:01:05,196 - __main__ - ERROR - Error retraining model: Model training failed: Feature preparation failed: Missing features in data: ['maxMissedStreak']
Traceback (most recent call last):
  File "E:\New folder (2)\adhd-assessment-system\backend\mlmodels\it21288326\retrain_model.py", line 1192, in prepare_features
    raise DataError(f"Missing features in data: {missing_features}")
DataError: Missing features in data: ['maxMissedStreak']

During handling of the above exception, another exception occurred:

Traceback (most recent call last):
  File "E:\New folder (2)\adhd-assessment-system\backend\mlmodels\it21288326\retrain_model.py", line 1219, in train_model
    X_scaled, scaler, feature_columns = prepare_features(data)
                                        ^^^^^^^^^^^^^^^^^^^^^^
  File "E:\New folder (2)\adhd-assessment-system\backend\mlmodels\it21288326\retrain_model.py", line 1207, in prepare_features
    raise DataError(f"Feature preparation failed: {str(e)}")
DataError: Feature preparation failed: Missing features in data: ['maxMissedStreak']

During handling of the above exception, another exception occurred:

Traceback (most recent call last):
  File "E:\New folder (2)\adhd-assessment-system\backend\mlmodels\it21288326\retrain_model.py", line 1753, in retrain_model
    model, scaler, feature_columns, label_mapping = train_model(data)
                                                    ^^^^^^^^^^^^^^^^^
  File "E:\New folder (2)\adhd-assessment-system\backend\mlmodels\it21288326\retrain_model.py", line 1289, in train_model
    raise ModelError(f"Model training failed: {str(e)}")
ModelError: Model training failed: Feature preparation failed: Missing features in data: ['maxMissedStreak']

2025-03-28 14:01:05,216 - werkzeug - INFO - 127.0.0.1 - - [28/Mar/2025 14:01:05] "[35m[1mPOST /retrain HTTP/1.1[0m" 500 -
2025-03-28 14:05:22,538 - werkzeug - INFO - 127.0.0.1 - - [28/Mar/2025 14:05:22] "GET /health HTTP/1.1" 200 -
2025-03-28 14:14:28,159 - __main__ - INFO - MongoDB connection established successfully
2025-03-28 14:14:31,600 - __main__ - INFO - Model loaded successfully
2025-03-28 14:14:31,600 - __main__ - INFO - Scaler loaded successfully
2025-03-28 14:14:31,600 - __main__ - INFO - Label encoder loaded successfully
2025-03-28 14:14:31,600 - __main__ - INFO - Starting prediction service on http://localhost:5000
2025-03-28 14:14:31,734 - werkzeug - INFO - [31m[1mWARNING: This is a development server. Do not use it in a production deployment. Use a production WSGI server instead.[0m
 * Running on all addresses (0.0.0.0)
 * Running on http://127.0.0.1:5000
 * Running on http://192.168.8.137:5000
2025-03-28 14:14:31,774 - werkzeug - INFO - [33mPress CTRL+C to quit[0m
2025-03-28 14:14:31,907 - werkzeug - INFO - 127.0.0.1 - - [28/Mar/2025 14:14:31] "GET /health HTTP/1.1" 200 -
2025-03-28 14:14:36,122 - werkzeug - INFO - 127.0.0.1 - - [28/Mar/2025 14:14:36] "OPTIONS /retrain HTTP/1.1" 200 -
2025-03-28 14:14:37,438 - __main__ - INFO - Loaded 200 records from CSV.
2025-03-28 14:15:08,171 - __main__ - INFO - Total dataset size: 200 records
2025-03-28 14:15:08,399 - __main__ - ERROR - Error in prepare_features: Missing features in data: ['maxMissedStreak']
Traceback (most recent call last):
  File "E:\New folder (2)\adhd-assessment-system\backend\mlmodels\it21288326\retrain_model.py", line 1192, in prepare_features
    raise DataError(f"Missing features in data: {missing_features}")
DataError: Missing features in data: ['maxMissedStreak']

2025-03-28 14:15:08,401 - __main__ - ERROR - Error in train_model: Feature preparation failed: Missing features in data: ['maxMissedStreak']
Traceback (most recent call last):
  File "E:\New folder (2)\adhd-assessment-system\backend\mlmodels\it21288326\retrain_model.py", line 1192, in prepare_features
    raise DataError(f"Missing features in data: {missing_features}")
DataError: Missing features in data: ['maxMissedStreak']

During handling of the above exception, another exception occurred:

Traceback (most recent call last):
  File "E:\New folder (2)\adhd-assessment-system\backend\mlmodels\it21288326\retrain_model.py", line 1219, in train_model
    X_scaled, scaler, feature_columns = prepare_features(data)
                                        ^^^^^^^^^^^^^^^^^^^^^^
  File "E:\New folder (2)\adhd-assessment-system\backend\mlmodels\it21288326\retrain_model.py", line 1207, in prepare_features
    raise DataError(f"Feature preparation failed: {str(e)}")
DataError: Feature preparation failed: Missing features in data: ['maxMissedStreak']

2025-03-28 14:15:08,410 - __main__ - ERROR - Error retraining model: Model training failed: Feature preparation failed: Missing features in data: ['maxMissedStreak']
Traceback (most recent call last):
  File "E:\New folder (2)\adhd-assessment-system\backend\mlmodels\it21288326\retrain_model.py", line 1192, in prepare_features
    raise DataError(f"Missing features in data: {missing_features}")
DataError: Missing features in data: ['maxMissedStreak']

During handling of the above exception, another exception occurred:

Traceback (most recent call last):
  File "E:\New folder (2)\adhd-assessment-system\backend\mlmodels\it21288326\retrain_model.py", line 1219, in train_model
    X_scaled, scaler, feature_columns = prepare_features(data)
                                        ^^^^^^^^^^^^^^^^^^^^^^
  File "E:\New folder (2)\adhd-assessment-system\backend\mlmodels\it21288326\retrain_model.py", line 1207, in prepare_features
    raise DataError(f"Feature preparation failed: {str(e)}")
DataError: Feature preparation failed: Missing features in data: ['maxMissedStreak']

During handling of the above exception, another exception occurred:

Traceback (most recent call last):
  File "E:\New folder (2)\adhd-assessment-system\backend\mlmodels\it21288326\retrain_model.py", line 1755, in retrain_model
    model, scaler, feature_columns, label_mapping = train_model(data)
                                                    ^^^^^^^^^^^^^^^^^
  File "E:\New folder (2)\adhd-assessment-system\backend\mlmodels\it21288326\retrain_model.py", line 1289, in train_model
    raise ModelError(f"Model training failed: {str(e)}")
ModelError: Model training failed: Feature preparation failed: Missing features in data: ['maxMissedStreak']

2025-03-28 14:15:08,418 - werkzeug - INFO - 127.0.0.1 - - [28/Mar/2025 14:15:08] "[35m[1mPOST /retrain HTTP/1.1[0m" 500 -
2025-03-28 14:15:22,317 - werkzeug - INFO - 127.0.0.1 - - [28/Mar/2025 14:15:22] "GET /health HTTP/1.1" 200 -
2025-03-28 14:17:40,850 - __main__ - INFO - MongoDB connection established successfully
2025-03-28 14:17:41,130 - __main__ - INFO - Model loaded successfully
2025-03-28 14:17:41,130 - __main__ - INFO - Scaler loaded successfully
2025-03-28 14:17:41,130 - __main__ - INFO - Label encoder loaded successfully
2025-03-28 14:17:41,130 - __main__ - INFO - Starting prediction service on http://localhost:5000
2025-03-28 14:17:41,148 - werkzeug - INFO - [31m[1mWARNING: This is a development server. Do not use it in a production deployment. Use a production WSGI server instead.[0m
 * Running on all addresses (0.0.0.0)
 * Running on http://127.0.0.1:5000
 * Running on http://192.168.8.137:5000
2025-03-28 14:17:41,149 - werkzeug - INFO - [33mPress CTRL+C to quit[0m
2025-03-28 14:18:40,063 - werkzeug - INFO - 127.0.0.1 - - [28/Mar/2025 14:18:40] "OPTIONS /retrain HTTP/1.1" 200 -
2025-03-28 14:18:40,331 - __main__ - INFO - Loaded 200 records from CSV.
2025-03-28 14:19:14,704 - __main__ - INFO - Total dataset size: 200 records
2025-03-28 14:19:14,710 - __main__ - ERROR - Error in prepare_features: Missing features in data: ['maxMissedStreak']
Traceback (most recent call last):
  File "E:\New folder (2)\adhd-assessment-system\backend\mlmodels\it21288326\retrain_model.py", line 1192, in prepare_features
    raise DataError(f"Missing features in data: {missing_features}")
DataError: Missing features in data: ['maxMissedStreak']

2025-03-28 14:19:14,713 - __main__ - ERROR - Error in train_model: Feature preparation failed: Missing features in data: ['maxMissedStreak']
Traceback (most recent call last):
  File "E:\New folder (2)\adhd-assessment-system\backend\mlmodels\it21288326\retrain_model.py", line 1192, in prepare_features
    raise DataError(f"Missing features in data: {missing_features}")
DataError: Missing features in data: ['maxMissedStreak']

During handling of the above exception, another exception occurred:

Traceback (most recent call last):
  File "E:\New folder (2)\adhd-assessment-system\backend\mlmodels\it21288326\retrain_model.py", line 1219, in train_model
    X_scaled, scaler, feature_columns = prepare_features(data)
                                        ^^^^^^^^^^^^^^^^^^^^^^
  File "E:\New folder (2)\adhd-assessment-system\backend\mlmodels\it21288326\retrain_model.py", line 1207, in prepare_features
    raise DataError(f"Feature preparation failed: {str(e)}")
DataError: Feature preparation failed: Missing features in data: ['maxMissedStreak']

2025-03-28 14:19:14,719 - __main__ - ERROR - Error retraining model: Model training failed: Feature preparation failed: Missing features in data: ['maxMissedStreak']
Traceback (most recent call last):
  File "E:\New folder (2)\adhd-assessment-system\backend\mlmodels\it21288326\retrain_model.py", line 1192, in prepare_features
    raise DataError(f"Missing features in data: {missing_features}")
DataError: Missing features in data: ['maxMissedStreak']

During handling of the above exception, another exception occurred:

Traceback (most recent call last):
  File "E:\New folder (2)\adhd-assessment-system\backend\mlmodels\it21288326\retrain_model.py", line 1219, in train_model
    X_scaled, scaler, feature_columns = prepare_features(data)
                                        ^^^^^^^^^^^^^^^^^^^^^^
  File "E:\New folder (2)\adhd-assessment-system\backend\mlmodels\it21288326\retrain_model.py", line 1207, in prepare_features
    raise DataError(f"Feature preparation failed: {str(e)}")
DataError: Feature preparation failed: Missing features in data: ['maxMissedStreak']

During handling of the above exception, another exception occurred:

Traceback (most recent call last):
  File "E:\New folder (2)\adhd-assessment-system\backend\mlmodels\it21288326\retrain_model.py", line 1758, in retrain_model
    model, scaler, feature_columns, label_mapping = train_model(data)
                                                    ^^^^^^^^^^^^^^^^^
  File "E:\New folder (2)\adhd-assessment-system\backend\mlmodels\it21288326\retrain_model.py", line 1289, in train_model
    raise ModelError(f"Model training failed: {str(e)}")
ModelError: Model training failed: Feature preparation failed: Missing features in data: ['maxMissedStreak']

2025-03-28 14:19:14,729 - werkzeug - INFO - 127.0.0.1 - - [28/Mar/2025 14:19:14] "[35m[1mPOST /retrain HTTP/1.1[0m" 500 -
2025-03-28 14:22:49,162 - __main__ - INFO - MongoDB connection established successfully
2025-03-28 14:22:50,198 - __main__ - INFO - Model loaded successfully
2025-03-28 14:22:50,211 - __main__ - INFO - Scaler loaded successfully
2025-03-28 14:22:50,213 - __main__ - INFO - Label encoder loaded successfully
2025-03-28 14:22:50,215 - __main__ - INFO - Starting prediction service on http://localhost:5000
2025-03-28 14:22:50,224 - werkzeug - INFO - [31m[1mWARNING: This is a development server. Do not use it in a production deployment. Use a production WSGI server instead.[0m
 * Running on all addresses (0.0.0.0)
 * Running on http://127.0.0.1:5000
 * Running on http://192.168.8.137:5000
2025-03-28 14:22:50,225 - werkzeug - INFO - [33mPress CTRL+C to quit[0m
2025-03-28 14:25:56,420 - werkzeug - INFO - 127.0.0.1 - - [28/Mar/2025 14:25:56] "GET /health HTTP/1.1" 200 -
2025-03-28 14:25:56,696 - werkzeug - INFO - 127.0.0.1 - - [28/Mar/2025 14:25:56] "GET /health HTTP/1.1" 200 -
2025-03-28 14:26:02,369 - werkzeug - INFO - 127.0.0.1 - - [28/Mar/2025 14:26:02] "OPTIONS /retrain HTTP/1.1" 200 -
2025-03-28 14:26:02,865 - __main__ - INFO - Loaded 200 records from CSV.
2025-03-28 14:26:42,525 - __main__ - INFO - Total dataset size: 200 records
2025-03-28 14:27:07,877 - __main__ - INFO - Test accuracy: 1.0000
2025-03-28 14:27:10,375 - __main__ - ERROR - Error in train_model: Object of type int64 is not JSON serializable
Traceback (most recent call last):
  File "E:\New folder (2)\adhd-assessment-system\backend\mlmodels\it21288326\retrain_model.py", line 1286, in train_model
    json.dump({
  File "C:\Users\User\AppData\Local\Programs\Python\Python311\Lib\json\__init__.py", line 179, in dump
    for chunk in iterable:
  File "C:\Users\User\AppData\Local\Programs\Python\Python311\Lib\json\encoder.py", line 432, in _iterencode
    yield from _iterencode_dict(o, _current_indent_level)
  File "C:\Users\User\AppData\Local\Programs\Python\Python311\Lib\json\encoder.py", line 406, in _iterencode_dict
    yield from chunks
  File "C:\Users\User\AppData\Local\Programs\Python\Python311\Lib\json\encoder.py", line 406, in _iterencode_dict
    yield from chunks
  File "C:\Users\User\AppData\Local\Programs\Python\Python311\Lib\json\encoder.py", line 439, in _iterencode
    o = _default(o)
        ^^^^^^^^^^^
  File "C:\Users\User\AppData\Local\Programs\Python\Python311\Lib\json\encoder.py", line 180, in default
    raise TypeError(f'Object of type {o.__class__.__name__} '
TypeError: Object of type int64 is not JSON serializable

2025-03-28 14:27:10,383 - __main__ - ERROR - Error retraining model: Model training failed: Object of type int64 is not JSON serializable
Traceback (most recent call last):
  File "E:\New folder (2)\adhd-assessment-system\backend\mlmodels\it21288326\retrain_model.py", line 1286, in train_model
    json.dump({
  File "C:\Users\User\AppData\Local\Programs\Python\Python311\Lib\json\__init__.py", line 179, in dump
    for chunk in iterable:
  File "C:\Users\User\AppData\Local\Programs\Python\Python311\Lib\json\encoder.py", line 432, in _iterencode
    yield from _iterencode_dict(o, _current_indent_level)
  File "C:\Users\User\AppData\Local\Programs\Python\Python311\Lib\json\encoder.py", line 406, in _iterencode_dict
    yield from chunks
  File "C:\Users\User\AppData\Local\Programs\Python\Python311\Lib\json\encoder.py", line 406, in _iterencode_dict
    yield from chunks
  File "C:\Users\User\AppData\Local\Programs\Python\Python311\Lib\json\encoder.py", line 439, in _iterencode
    o = _default(o)
        ^^^^^^^^^^^
  File "C:\Users\User\AppData\Local\Programs\Python\Python311\Lib\json\encoder.py", line 180, in default
    raise TypeError(f'Object of type {o.__class__.__name__} '
TypeError: Object of type int64 is not JSON serializable

During handling of the above exception, another exception occurred:

Traceback (most recent call last):
  File "E:\New folder (2)\adhd-assessment-system\backend\mlmodels\it21288326\retrain_model.py", line 1764, in retrain_model
    model, scaler, feature_columns, label_mapping = train_model(data)
                                                    ^^^^^^^^^^^^^^^^^
  File "E:\New folder (2)\adhd-assessment-system\backend\mlmodels\it21288326\retrain_model.py", line 1295, in train_model
    raise ModelError(f"Model training failed: {str(e)}")
ModelError: Model training failed: Object of type int64 is not JSON serializable

2025-03-28 14:27:10,409 - werkzeug - INFO - 127.0.0.1 - - [28/Mar/2025 14:27:10] "[35m[1mPOST /retrain HTTP/1.1[0m" 500 -
2025-03-28 14:34:10,472 - werkzeug - INFO - 127.0.0.1 - - [28/Mar/2025 14:34:10] "GET /health HTTP/1.1" 200 -
2025-03-28 14:34:18,305 - werkzeug - INFO - 127.0.0.1 - - [28/Mar/2025 14:34:18] "GET /health HTTP/1.1" 200 -
2025-03-28 14:34:19,914 - werkzeug - INFO - 127.0.0.1 - - [28/Mar/2025 14:34:19] "GET /health HTTP/1.1" 200 -
2025-03-28 14:34:24,596 - werkzeug - INFO - 127.0.0.1 - - [28/Mar/2025 14:34:24] "GET /health HTTP/1.1" 200 -
2025-03-28 14:34:29,554 - werkzeug - INFO - 127.0.0.1 - - [28/Mar/2025 14:34:29] "GET /health HTTP/1.1" 200 -
2025-03-28 14:34:40,761 - werkzeug - INFO - 127.0.0.1 - - [28/Mar/2025 14:34:40] "OPTIONS /retrain HTTP/1.1" 200 -
2025-03-28 14:34:41,071 - __main__ - INFO - Loaded 200 records from CSV.
2025-03-28 14:35:14,437 - __main__ - INFO - Total dataset size: 200 records
2025-03-28 14:35:21,911 - __main__ - INFO - Test accuracy: 1.0000
2025-03-28 14:35:21,939 - __main__ - ERROR - Error in train_model: Object of type int64 is not JSON serializable
Traceback (most recent call last):
  File "E:\New folder (2)\adhd-assessment-system\backend\mlmodels\it21288326\retrain_model.py", line 1286, in train_model
    json.dump({
  File "C:\Users\User\AppData\Local\Programs\Python\Python311\Lib\json\__init__.py", line 179, in dump
    for chunk in iterable:
  File "C:\Users\User\AppData\Local\Programs\Python\Python311\Lib\json\encoder.py", line 432, in _iterencode
    yield from _iterencode_dict(o, _current_indent_level)
  File "C:\Users\User\AppData\Local\Programs\Python\Python311\Lib\json\encoder.py", line 406, in _iterencode_dict
    yield from chunks
  File "C:\Users\User\AppData\Local\Programs\Python\Python311\Lib\json\encoder.py", line 406, in _iterencode_dict
    yield from chunks
  File "C:\Users\User\AppData\Local\Programs\Python\Python311\Lib\json\encoder.py", line 439, in _iterencode
    o = _default(o)
        ^^^^^^^^^^^
  File "C:\Users\User\AppData\Local\Programs\Python\Python311\Lib\json\encoder.py", line 180, in default
    raise TypeError(f'Object of type {o.__class__.__name__} '
TypeError: Object of type int64 is not JSON serializable

2025-03-28 14:35:21,947 - __main__ - ERROR - Error retraining model: Model training failed: Object of type int64 is not JSON serializable
Traceback (most recent call last):
  File "E:\New folder (2)\adhd-assessment-system\backend\mlmodels\it21288326\retrain_model.py", line 1286, in train_model
    json.dump({
  File "C:\Users\User\AppData\Local\Programs\Python\Python311\Lib\json\__init__.py", line 179, in dump
    for chunk in iterable:
  File "C:\Users\User\AppData\Local\Programs\Python\Python311\Lib\json\encoder.py", line 432, in _iterencode
    yield from _iterencode_dict(o, _current_indent_level)
  File "C:\Users\User\AppData\Local\Programs\Python\Python311\Lib\json\encoder.py", line 406, in _iterencode_dict
    yield from chunks
  File "C:\Users\User\AppData\Local\Programs\Python\Python311\Lib\json\encoder.py", line 406, in _iterencode_dict
    yield from chunks
  File "C:\Users\User\AppData\Local\Programs\Python\Python311\Lib\json\encoder.py", line 439, in _iterencode
    o = _default(o)
        ^^^^^^^^^^^
  File "C:\Users\User\AppData\Local\Programs\Python\Python311\Lib\json\encoder.py", line 180, in default
    raise TypeError(f'Object of type {o.__class__.__name__} '
TypeError: Object of type int64 is not JSON serializable

During handling of the above exception, another exception occurred:

Traceback (most recent call last):
  File "E:\New folder (2)\adhd-assessment-system\backend\mlmodels\it21288326\retrain_model.py", line 1764, in retrain_model
    model, scaler, feature_columns, label_mapping = train_model(data)
                                                    ^^^^^^^^^^^^^^^^^
  File "E:\New folder (2)\adhd-assessment-system\backend\mlmodels\it21288326\retrain_model.py", line 1295, in train_model
    raise ModelError(f"Model training failed: {str(e)}")
ModelError: Model training failed: Object of type int64 is not JSON serializable

2025-03-28 14:35:22,171 - werkzeug - INFO - 127.0.0.1 - - [28/Mar/2025 14:35:22] "[35m[1mPOST /retrain HTTP/1.1[0m" 500 -
2025-03-28 14:35:59,185 - werkzeug - INFO - 127.0.0.1 - - [28/Mar/2025 14:35:59] "GET /health HTTP/1.1" 200 -
2025-03-28 14:40:57,319 - werkzeug - INFO - 127.0.0.1 - - [28/Mar/2025 14:40:57] "GET /health HTTP/1.1" 200 -
2025-03-28 14:45:20,963 - __main__ - INFO - MongoDB connection established successfully
2025-03-28 14:45:22,050 - __main__ - INFO - Model loaded successfully
2025-03-28 14:45:22,066 - __main__ - INFO - Scaler loaded successfully
2025-03-28 14:45:22,066 - __main__ - INFO - Label encoder loaded successfully
2025-03-28 14:45:22,066 - __main__ - INFO - Starting prediction service on http://localhost:5000
2025-03-28 14:45:22,089 - werkzeug - INFO - [31m[1mWARNING: This is a development server. Do not use it in a production deployment. Use a production WSGI server instead.[0m
 * Running on all addresses (0.0.0.0)
 * Running on http://127.0.0.1:5000
 * Running on http://192.168.8.137:5000
2025-03-28 14:45:22,089 - werkzeug - INFO - [33mPress CTRL+C to quit[0m
2025-03-28 14:45:35,374 - werkzeug - INFO - 127.0.0.1 - - [28/Mar/2025 14:45:35] "OPTIONS /retrain HTTP/1.1" 200 -
2025-03-28 14:45:35,719 - __main__ - INFO - Loaded 200 records from CSV.
2025-03-28 14:45:58,411 - werkzeug - INFO - 127.0.0.1 - - [28/Mar/2025 14:45:58] "GET /health HTTP/1.1" 200 -
2025-03-28 14:46:59,798 - __main__ - ERROR - Error fetching data from MongoDB: cluster0-shard-00-01.a1s53.mongodb.net:27017: timed out (configured timeouts: connectTimeoutMS: 20000.0ms)
2025-03-28 14:47:07,971 - __main__ - INFO - Test accuracy: 1.0000
2025-03-28 14:47:08,007 - __main__ - INFO - Model retrained and saved with preprocessing information.
2025-03-28 14:47:08,009 - werkzeug - INFO - 127.0.0.1 - - [28/Mar/2025 14:47:08] "POST /retrain HTTP/1.1" 200 -
2025-03-28 14:47:55,216 - werkzeug - INFO - 127.0.0.1 - - [28/Mar/2025 14:47:55] "OPTIONS /retrain HTTP/1.1" 200 -
2025-03-28 14:47:55,485 - __main__ - INFO - Loaded 200 records from CSV.
2025-03-28 14:48:19,549 - __main__ - ERROR - Error fetching data from MongoDB: cluster0-shard-00-01.a1s53.mongodb.net:27017: timed out (configured timeouts: connectTimeoutMS: 20000.0ms)
2025-03-28 14:48:30,564 - __main__ - INFO - Test accuracy: 1.0000
2025-03-28 14:48:30,601 - __main__ - INFO - Model retrained and saved with preprocessing information.
2025-03-28 14:48:30,601 - werkzeug - INFO - 127.0.0.1 - - [28/Mar/2025 14:48:30] "POST /retrain HTTP/1.1" 200 -
2025-03-28 14:50:58,940 - werkzeug - INFO - 127.0.0.1 - - [28/Mar/2025 14:50:58] "GET /health HTTP/1.1" 200 -
2025-03-28 14:56:01,336 - werkzeug - INFO - 127.0.0.1 - - [28/Mar/2025 14:56:01] "GET /health HTTP/1.1" 200 -
2025-03-28 15:01:01,342 - werkzeug - INFO - 127.0.0.1 - - [28/Mar/2025 15:01:01] "GET /health HTTP/1.1" 200 -
2025-03-28 15:06:01,347 - werkzeug - INFO - 127.0.0.1 - - [28/Mar/2025 15:06:01] "GET /health HTTP/1.1" 200 -
2025-03-28 15:11:01,311 - werkzeug - INFO - 127.0.0.1 - - [28/Mar/2025 15:11:01] "GET /health HTTP/1.1" 200 -
2025-03-28 15:16:01,313 - werkzeug - INFO - 127.0.0.1 - - [28/Mar/2025 15:16:01] "GET /health HTTP/1.1" 200 -
2025-03-28 15:21:01,292 - werkzeug - INFO - 127.0.0.1 - - [28/Mar/2025 15:21:01] "GET /health HTTP/1.1" 200 -
2025-03-28 15:26:01,300 - werkzeug - INFO - 127.0.0.1 - - [28/Mar/2025 15:26:01] "GET /health HTTP/1.1" 200 -
2025-03-28 16:04:23,257 - werkzeug - INFO - 127.0.0.1 - - [28/Mar/2025 16:04:23] "GET /health HTTP/1.1" 200 -
2025-03-28 16:06:02,005 - werkzeug - INFO - 127.0.0.1 - - [28/Mar/2025 16:06:02] "GET /health HTTP/1.1" 200 -
2025-03-28 16:11:01,274 - werkzeug - INFO - 127.0.0.1 - - [28/Mar/2025 16:11:01] "GET /health HTTP/1.1" 200 -
2025-03-28 16:16:01,283 - werkzeug - INFO - 127.0.0.1 - - [28/Mar/2025 16:16:01] "GET /health HTTP/1.1" 200 -
2025-03-28 16:21:02,640 - werkzeug - INFO - 127.0.0.1 - - [28/Mar/2025 16:21:02] "GET /health HTTP/1.1" 200 -
2025-03-28 16:26:02,134 - werkzeug - INFO - 127.0.0.1 - - [28/Mar/2025 16:26:02] "GET /health HTTP/1.1" 200 -
2025-03-28 16:31:01,288 - werkzeug - INFO - 127.0.0.1 - - [28/Mar/2025 16:31:01] "GET /health HTTP/1.1" 200 -
2025-03-28 16:36:01,312 - werkzeug - INFO - 127.0.0.1 - - [28/Mar/2025 16:36:01] "GET /health HTTP/1.1" 200 -
2025-03-28 16:41:01,304 - werkzeug - INFO - 127.0.0.1 - - [28/Mar/2025 16:41:01] "GET /health HTTP/1.1" 200 -
2025-03-28 16:46:01,296 - werkzeug - INFO - 127.0.0.1 - - [28/Mar/2025 16:46:01] "GET /health HTTP/1.1" 200 -
2025-03-28 16:51:01,299 - werkzeug - INFO - 127.0.0.1 - - [28/Mar/2025 16:51:01] "GET /health HTTP/1.1" 200 -
2025-03-28 16:56:03,853 - werkzeug - INFO - 127.0.0.1 - - [28/Mar/2025 16:56:03] "GET /health HTTP/1.1" 200 -
2025-03-28 19:12:33,115 - werkzeug - INFO - 127.0.0.1 - - [28/Mar/2025 19:12:33] "GET /health HTTP/1.1" 200 -
2025-04-07 18:06:41,526 - __main__ - INFO - MongoDB connection established successfully
2025-04-07 18:06:41,591 - __main__ - ERROR - Error loading model from E:/New folder (2)/adhd-assessment-system/backend/mlmodels/it21288326/adhd_model.keras: No file or directory found at E:/New folder (2)/adhd-assessment-system/backend/mlmodels/it21288326/adhd_model.keras
2025-04-07 18:06:41,592 - __main__ - ERROR - Error loading model from fallback location: No file or directory found at adhd_model_fallback.keras
2025-04-07 18:06:41,592 - __main__ - ERROR - Error: Could not load model. Please train the model first.
2025-04-07 18:06:41,593 - __main__ - INFO - Starting prediction service on http://localhost:5000
2025-04-07 18:06:41,614 - werkzeug - INFO - [31m[1mWARNING: This is a development server. Do not use it in a production deployment. Use a production WSGI server instead.[0m
 * Running on all addresses (0.0.0.0)
 * Running on http://127.0.0.1:5000
 * Running on http://192.168.8.237:5000
2025-04-07 18:06:41,615 - werkzeug - INFO - [33mPress CTRL+C to quit[0m
2025-04-07 18:15:05,931 - werkzeug - INFO - 127.0.0.1 - - [07/Apr/2025 18:15:05] "OPTIONS /predict HTTP/1.1" 200 -
2025-04-07 18:15:05,931 - werkzeug - INFO - 127.0.0.1 - - [07/Apr/2025 18:15:05] "OPTIONS /predict HTTP/1.1" 200 -
2025-04-07 18:15:06,047 - werkzeug - INFO - 127.0.0.1 - - [07/Apr/2025 18:15:06] "OPTIONS /predict HTTP/1.1" 200 -
2025-04-07 18:15:06,147 - __main__ - ERROR - Error loading model from E:/New folder (2)/adhd-assessment-system/backend/mlmodels/it21288326/adhd_model.keras: No file or directory found at E:/New folder (2)/adhd-assessment-system/backend/mlmodels/it21288326/adhd_model.keras
2025-04-07 18:15:06,147 - __main__ - ERROR - Error loading model from fallback location: No file or directory found at adhd_model_fallback.keras
2025-04-07 18:15:06,147 - __main__ - ERROR - Model error in predict_adhd_type: Failed to load model
2025-04-07 18:15:06,163 - __main__ - INFO - Successfully processed prediction for game data
2025-04-07 18:15:06,163 - werkzeug - INFO - 127.0.0.1 - - [07/Apr/2025 18:15:06] "POST /predict HTTP/1.1" 200 -
2025-04-07 18:15:06,266 - __main__ - ERROR - Error loading model from E:/New folder (2)/adhd-assessment-system/backend/mlmodels/it21288326/adhd_model.keras: No file or directory found at E:/New folder (2)/adhd-assessment-system/backend/mlmodels/it21288326/adhd_model.keras
2025-04-07 18:15:06,268 - __main__ - ERROR - Error loading model from fallback location: No file or directory found at adhd_model_fallback.keras
2025-04-07 18:15:06,268 - __main__ - ERROR - Model error in predict_adhd_type: Failed to load model
2025-04-07 18:15:06,270 - __main__ - INFO - Successfully processed prediction for game data
2025-04-07 18:15:06,270 - __main__ - ERROR - Error loading model from E:/New folder (2)/adhd-assessment-system/backend/mlmodels/it21288326/adhd_model.keras: No file or directory found at E:/New folder (2)/adhd-assessment-system/backend/mlmodels/it21288326/adhd_model.keras
2025-04-07 18:15:06,270 - werkzeug - INFO - 127.0.0.1 - - [07/Apr/2025 18:15:06] "POST /predict HTTP/1.1" 200 -
2025-04-07 18:15:06,270 - __main__ - ERROR - Error loading model from fallback location: No file or directory found at adhd_model_fallback.keras
2025-04-07 18:15:06,270 - __main__ - ERROR - Model error in predict_adhd_type: Failed to load model
2025-04-07 18:15:06,277 - __main__ - INFO - Successfully processed prediction for game data
2025-04-07 18:15:06,279 - werkzeug - INFO - 127.0.0.1 - - [07/Apr/2025 18:15:06] "POST /predict HTTP/1.1" 200 -
2025-04-07 18:20:22,009 - werkzeug - INFO - 127.0.0.1 - - [07/Apr/2025 18:20:22] "GET /health HTTP/1.1" 200 -
2025-04-07 18:20:22,222 - werkzeug - INFO - 127.0.0.1 - - [07/Apr/2025 18:20:22] "GET /health HTTP/1.1" 200 -
2025-04-07 18:22:56,565 - __main__ - INFO - MongoDB connection established successfully
2025-04-07 18:22:56,631 - __main__ - ERROR - Error loading model from E:/New folder (2)/adhd-assessment-system/backend/mlmodels/it21288326/adhd_model.keras: No file or directory found at E:/New folder (2)/adhd-assessment-system/backend/mlmodels/it21288326/adhd_model.keras
2025-04-07 18:22:56,631 - __main__ - ERROR - Error loading model from fallback location: No file or directory found at adhd_model_fallback.keras
2025-04-07 18:22:56,631 - __main__ - ERROR - Error: Could not load model. Please train the model first.
2025-04-07 18:22:56,632 - __main__ - INFO - Starting prediction service on http://localhost:5000
2025-04-07 18:22:56,647 - werkzeug - INFO - [31m[1mWARNING: This is a development server. Do not use it in a production deployment. Use a production WSGI server instead.[0m
 * Running on all addresses (0.0.0.0)
 * Running on http://127.0.0.1:5000
 * Running on http://192.168.8.237:5000
2025-04-07 18:22:56,648 - werkzeug - INFO - [33mPress CTRL+C to quit[0m
2025-04-07 18:24:58,035 - __main__ - INFO - MongoDB connection established successfully
2025-04-07 18:24:58,075 - __main__ - ERROR - Error loading model from E:/New folder (2)/adhd-assessment-system/backend/mlmodels/it21288326/adhd_model.keras: No file or directory found at E:/New folder (2)/adhd-assessment-system/backend/mlmodels/it21288326/adhd_model.keras
2025-04-07 18:24:58,087 - __main__ - ERROR - Error loading model from fallback location: No file or directory found at adhd_model_fallback.keras
2025-04-07 18:24:58,087 - __main__ - ERROR - Error: Could not load model. Please train the model first.
2025-04-07 18:24:58,088 - __main__ - INFO - Starting prediction service on http://localhost:5000
2025-04-07 18:24:58,092 - werkzeug - INFO - [31m[1mWARNING: This is a development server. Do not use it in a production deployment. Use a production WSGI server instead.[0m
 * Running on all addresses (0.0.0.0)
 * Running on http://127.0.0.1:5000
 * Running on http://192.168.8.237:5000
2025-04-07 18:24:58,092 - werkzeug - INFO - [33mPress CTRL+C to quit[0m
2025-04-07 18:25:23,360 - __main__ - INFO - MongoDB connection established successfully
2025-04-07 18:25:23,474 - __main__ - ERROR - Error loading model from C:/Users/shash/Documents/GitHub/adhd-assessment-system/backend/mlmodels/it21288326/adhd_model.keras: Error when deserializing class 'InputLayer' using config={'batch_shape': [None, 7], 'dtype': 'float32', 'sparse': False, 'name': 'input_layer'}.

Exception encountered: Unrecognized keyword arguments: ['batch_shape']
2025-04-07 18:25:23,474 - __main__ - ERROR - Error loading model from fallback location: No file or directory found at adhd_model_fallback.keras
2025-04-07 18:25:23,474 - __main__ - ERROR - Error: Could not load model. Please train the model first.
2025-04-07 18:25:23,474 - __main__ - INFO - Starting prediction service on http://localhost:5000
2025-04-07 18:25:23,493 - werkzeug - INFO - [31m[1mWARNING: This is a development server. Do not use it in a production deployment. Use a production WSGI server instead.[0m
 * Running on all addresses (0.0.0.0)
 * Running on http://127.0.0.1:5000
 * Running on http://192.168.8.237:5000
2025-04-07 18:25:23,493 - werkzeug - INFO - [33mPress CTRL+C to quit[0m
2025-04-07 18:25:23,762 - werkzeug - INFO - 127.0.0.1 - - [07/Apr/2025 18:25:23] "GET /health HTTP/1.1" 200 -
2025-04-07 18:26:59,213 - __main__ - ERROR - MongoDB connection error: The resolution lifetime expired after 21.621 seconds: Server Do53:192.168.8.1@53 answered The DNS operation timed out.; Server Do53:192.168.1.1@53 answered The DNS operation timed out.; Server Do53:192.168.8.1@53 answered The DNS operation timed out.; Server Do53:192.168.1.1@53 answered The DNS operation timed out.; Server Do53:192.168.8.1@53 answered The DNS operation timed out.; Server Do53:192.168.1.1@53 answered The DNS operation timed out.; Server Do53:192.168.8.1@53 answered The DNS operation timed out.; Server Do53:192.168.1.1@53 answered The DNS operation timed out.; Server Do53:192.168.8.1@53 answered The DNS operation timed out.; Server Do53:192.168.1.1@53 answered The DNS operation timed out.
2025-04-07 18:26:59,298 - __main__ - ERROR - Error loading model from C:/Users/shash/Documents/GitHub/adhd-assessment-system/backend/mlmodels/it21288326/adhd_model.keras: Error when deserializing class 'InputLayer' using config={'batch_shape': [None, 7], 'dtype': 'float32', 'sparse': False, 'name': 'input_layer'}.

Exception encountered: Unrecognized keyword arguments: ['batch_shape']
2025-04-07 18:26:59,298 - __main__ - ERROR - Error loading model from fallback location: No file or directory found at adhd_model_fallback.keras
2025-04-07 18:26:59,298 - __main__ - ERROR - Error: Could not load model. Please train the model first.
2025-04-07 18:26:59,298 - __main__ - INFO - Starting prediction service on http://localhost:5000
2025-04-07 18:26:59,319 - werkzeug - INFO - [31m[1mWARNING: This is a development server. Do not use it in a production deployment. Use a production WSGI server instead.[0m
 * Running on all addresses (0.0.0.0)
 * Running on http://127.0.0.1:5000
 * Running on http://192.168.8.237:5000
2025-04-07 18:26:59,319 - werkzeug - INFO - [33mPress CTRL+C to quit[0m
2025-04-07 18:32:02,900 - __main__ - INFO - MongoDB connection established successfully
2025-04-07 18:32:02,976 - __main__ - ERROR - Error loading model from C:/Users/shash/Documents/GitHub/adhd-assessment-system/backend/mlmodels/it21288326/adhd_model.keras: Error when deserializing class 'InputLayer' using config={'batch_shape': [None, 7], 'dtype': 'float32', 'sparse': False, 'name': 'input_layer'}.

Exception encountered: Unrecognized keyword arguments: ['batch_shape']
2025-04-07 18:32:02,978 - __main__ - ERROR - Error loading model from fallback location: No file or directory found at adhd_model_fallback.keras
2025-04-07 18:32:02,978 - __main__ - ERROR - Error: Could not load model. Please train the model first.
2025-04-07 18:32:02,979 - __main__ - INFO - Starting prediction service on http://localhost:5000
2025-04-07 18:32:02,986 - werkzeug - INFO - [31m[1mWARNING: This is a development server. Do not use it in a production deployment. Use a production WSGI server instead.[0m
 * Running on all addresses (0.0.0.0)
 * Running on http://127.0.0.1:5000
 * Running on http://192.168.8.237:5000
2025-04-07 18:32:02,987 - werkzeug - INFO - [33mPress CTRL+C to quit[0m
2025-04-07 18:33:43,928 - werkzeug - INFO - 127.0.0.1 - - [07/Apr/2025 18:33:43] "GET /health HTTP/1.1" 200 -
2025-04-07 18:35:22,654 - werkzeug - INFO - 127.0.0.1 - - [07/Apr/2025 18:35:22] "GET /health HTTP/1.1" 200 -
2025-04-07 18:36:24,350 - __main__ - INFO - MongoDB connection established successfully
2025-04-07 18:36:24,520 - __main__ - ERROR - Error loading model from C:/Users/shash/Documents/GitHub/adhd-assessment-system/backend/mlmodels/it21288326/adhd_model.keras: Error when deserializing class 'InputLayer' using config={'batch_shape': [None, 7], 'dtype': 'float32', 'sparse': False, 'name': 'input_layer'}.

Exception encountered: Unrecognized keyword arguments: ['batch_shape']
2025-04-07 18:36:24,520 - __main__ - ERROR - Error loading model from fallback location: No file or directory found at adhd_model_fallback.keras
2025-04-07 18:36:24,520 - __main__ - ERROR - Error: Could not load model. Please train the model first.
2025-04-07 18:36:24,525 - __main__ - INFO - Starting prediction service on http://localhost:5000
2025-04-07 18:36:24,537 - werkzeug - INFO - [31m[1mWARNING: This is a development server. Do not use it in a production deployment. Use a production WSGI server instead.[0m
 * Running on all addresses (0.0.0.0)
 * Running on http://127.0.0.1:5000
 * Running on http://192.168.8.237:5000
2025-04-07 18:36:24,537 - werkzeug - INFO - [33mPress CTRL+C to quit[0m
2025-04-07 18:38:59,252 - __main__ - INFO - MongoDB connection established successfully
2025-04-07 18:38:59,288 - __main__ - ERROR - Error loading model from backend/mlmodels/it21288326/adhd_model.keras: No file or directory found at backend/mlmodels/it21288326/adhd_model.keras
2025-04-07 18:38:59,288 - __main__ - ERROR - Error loading model from fallback location: No file or directory found at adhd_model_fallback.keras
2025-04-07 18:38:59,288 - __main__ - ERROR - Error: Could not load model. Please train the model first.
2025-04-07 18:38:59,288 - __main__ - INFO - Starting prediction service on http://localhost:5000
2025-04-07 18:38:59,309 - werkzeug - INFO - [31m[1mWARNING: This is a development server. Do not use it in a production deployment. Use a production WSGI server instead.[0m
 * Running on all addresses (0.0.0.0)
 * Running on http://127.0.0.1:5000
 * Running on http://192.168.8.237:5000
2025-04-07 18:38:59,309 - werkzeug - INFO - [33mPress CTRL+C to quit[0m
2025-04-07 18:41:06,043 - __main__ - INFO - MongoDB connection established successfully
2025-04-07 18:41:06,141 - __main__ - ERROR - Error loading model from backend/mlmodels/it21288326/adhd_model.keras: No file or directory found at backend/mlmodels/it21288326/adhd_model.keras
2025-04-07 18:41:06,142 - __main__ - ERROR - Error loading model from fallback location: No file or directory found at adhd_model_fallback.keras
2025-04-07 18:41:06,142 - __main__ - ERROR - Error: Could not load model. Please train the model first.
2025-04-07 18:41:06,142 - __main__ - INFO - Starting prediction service on http://localhost:5000
2025-04-07 18:41:06,175 - werkzeug - INFO - [31m[1mWARNING: This is a development server. Do not use it in a production deployment. Use a production WSGI server instead.[0m
 * Running on all addresses (0.0.0.0)
 * Running on http://127.0.0.1:5000
 * Running on http://192.168.8.237:5000
2025-04-07 18:41:06,176 - werkzeug - INFO - [33mPress CTRL+C to quit[0m
2025-04-07 18:44:48,584 - __main__ - INFO - MongoDB connection established successfully
2025-04-07 18:44:48,718 - __main__ - ERROR - Error loading model from C:/Users/shash/Documents/GitHub/adhd-assessment-system/backend/mlmodels/it21288326/adhd_model.keras: Error when deserializing class 'InputLayer' using config={'batch_shape': [None, 7], 'dtype': 'float32', 'sparse': False, 'name': 'input_layer'}.

Exception encountered: Unrecognized keyword arguments: ['batch_shape']
2025-04-07 18:44:48,719 - __main__ - ERROR - Error loading model from fallback location: No file or directory found at adhd_model_fallback.keras
2025-04-07 18:44:48,719 - __main__ - ERROR - Error: Could not load model. Please train the model first.
2025-04-07 18:44:48,719 - __main__ - INFO - Starting prediction service on http://localhost:5000
2025-04-07 18:44:48,744 - werkzeug - INFO - [31m[1mWARNING: This is a development server. Do not use it in a production deployment. Use a production WSGI server instead.[0m
 * Running on all addresses (0.0.0.0)
 * Running on http://127.0.0.1:5000
 * Running on http://192.168.8.237:5000
2025-04-07 18:44:48,745 - werkzeug - INFO - [33mPress CTRL+C to quit[0m
2025-04-07 21:14:17,970 - __main__ - INFO - MongoDB connection established successfully
2025-04-07 21:14:18,087 - __main__ - ERROR - Error loading model from C:/Users/shash/Documents/GitHub/adhd-assessment-system/backend/mlmodels/it21288326/adhd_model.keras: Error when deserializing class 'InputLayer' using config={'batch_shape': [None, 7], 'dtype': 'float32', 'sparse': False, 'name': 'input_layer'}.

Exception encountered: Unrecognized keyword arguments: ['batch_shape']
2025-04-07 21:14:18,087 - __main__ - ERROR - Error loading model from fallback location: No file or directory found at adhd_model_fallback.keras
2025-04-07 21:14:18,087 - __main__ - ERROR - Error: Could not load model. Please train the model first.
2025-04-07 21:14:18,087 - __main__ - INFO - Starting prediction service on http://localhost:5000
2025-04-07 21:14:18,123 - werkzeug - INFO - [31m[1mWARNING: This is a development server. Do not use it in a production deployment. Use a production WSGI server instead.[0m
 * Running on all addresses (0.0.0.0)
 * Running on http://127.0.0.1:5000
 * Running on http://192.168.8.237:5000
2025-04-07 21:14:18,123 - werkzeug - INFO - [33mPress CTRL+C to quit[0m
2025-04-07 21:18:06,799 - __main__ - INFO - MongoDB connection established successfully
2025-04-07 21:18:06,875 - __main__ - ERROR - Error loading model from C:/Users/shash/Documents/GitHub/adhd-assessment-system/backend/mlmodels/it21288326/adhd_model.keras: Error when deserializing class 'InputLayer' using config={'batch_shape': [None, 7], 'dtype': 'float32', 'sparse': False, 'name': 'input_layer'}.

Exception encountered: Unrecognized keyword arguments: ['batch_shape']
2025-04-07 21:18:06,875 - __main__ - ERROR - Error loading model from fallback location: No file or directory found at adhd_model_fallback.keras
2025-04-07 21:18:06,875 - __main__ - ERROR - Error: Could not load model. Please train the model first.
2025-04-07 21:18:06,878 - __main__ - INFO - Starting prediction service on http://localhost:5000
2025-04-07 21:18:06,885 - werkzeug - INFO - [31m[1mWARNING: This is a development server. Do not use it in a production deployment. Use a production WSGI server instead.[0m
 * Running on all addresses (0.0.0.0)
 * Running on http://127.0.0.1:5000
 * Running on http://192.168.8.237:5000
2025-04-07 21:18:06,885 - werkzeug - INFO - [33mPress CTRL+C to quit[0m
2025-04-07 22:49:24,531 - __main__ - INFO - MongoDB connection established successfully
2025-04-07 22:49:24,620 - __main__ - ERROR - Error loading model from C:/Users/shash/Documents/GitHub/adhd-assessment-system/backend/mlmodels/it21288326/adhd_model.keras: Error when deserializing class 'InputLayer' using config={'batch_shape': [None, 7], 'dtype': 'float32', 'sparse': False, 'name': 'input_layer'}.

Exception encountered: Unrecognized keyword arguments: ['batch_shape']
2025-04-07 22:49:24,620 - __main__ - ERROR - Error loading model from fallback location: No file or directory found at adhd_model_fallback.keras
2025-04-07 22:49:24,620 - __main__ - ERROR - Error: Could not load model. Please train the model first.
2025-04-07 22:49:24,620 - __main__ - INFO - Starting prediction service on http://localhost:5000
2025-04-07 22:49:24,639 - werkzeug - INFO - [31m[1mWARNING: This is a development server. Do not use it in a production deployment. Use a production WSGI server instead.[0m
 * Running on all addresses (0.0.0.0)
 * Running on http://127.0.0.1:5000
 * Running on http://192.168.8.237:5000
2025-04-07 22:49:24,639 - werkzeug - INFO - [33mPress CTRL+C to quit[0m
2025-04-07 23:32:09,720 - __main__ - INFO - MongoDB connection established successfully
2025-04-07 23:32:09,811 - __main__ - ERROR - Error loading model from C:/Users/shash/Documents/GitHub/adhd-assessment-system/backend/mlmodels/it21288326/adhd_model.keras: Error when deserializing class 'InputLayer' using config={'batch_shape': [None, 7], 'dtype': 'float32', 'sparse': False, 'name': 'input_layer'}.

Exception encountered: Unrecognized keyword arguments: ['batch_shape']
2025-04-07 23:32:09,824 - __main__ - ERROR - Error loading model from fallback location: No file or directory found at adhd_model_fallback.keras
2025-04-07 23:32:09,825 - __main__ - ERROR - Error: Could not load model. Please train the model first.
2025-04-07 23:32:09,825 - __main__ - INFO - Starting prediction service on http://localhost:5000
2025-04-07 23:32:09,864 - werkzeug - INFO - [31m[1mWARNING: This is a development server. Do not use it in a production deployment. Use a production WSGI server instead.[0m
 * Running on all addresses (0.0.0.0)
 * Running on http://127.0.0.1:5000
 * Running on http://192.168.8.237:5000
2025-04-07 23:32:09,864 - werkzeug - INFO - [33mPress CTRL+C to quit[0m
2025-04-07 23:40:45,786 - __main__ - INFO - MongoDB connection established successfully
2025-04-07 23:40:45,872 - __main__ - ERROR - Error loading model from C:/Users/shash/Documents/GitHub/adhd-assessment-system/backend/mlmodels/it21288326/adhd_model.keras: Error when deserializing class 'InputLayer' using config={'batch_shape': [None, 7], 'dtype': 'float32', 'sparse': False, 'name': 'input_layer'}.

Exception encountered: Unrecognized keyword arguments: ['batch_shape']
2025-04-07 23:40:45,874 - __main__ - ERROR - Error loading model from fallback location: No file or directory found at adhd_model_fallback.keras
2025-04-07 23:40:45,875 - __main__ - ERROR - Error: Could not load model. Please train the model first.
2025-04-07 23:40:45,875 - __main__ - INFO - Starting prediction service on http://localhost:5000
2025-04-07 23:40:45,894 - werkzeug - INFO - [31m[1mWARNING: This is a development server. Do not use it in a production deployment. Use a production WSGI server instead.[0m
 * Running on all addresses (0.0.0.0)
 * Running on http://127.0.0.1:5000
 * Running on http://192.168.8.237:5000
2025-04-07 23:40:45,894 - werkzeug - INFO - [33mPress CTRL+C to quit[0m
2025-04-07 23:41:53,354 - __main__ - INFO - MongoDB connection established successfully
2025-04-07 23:41:53,425 - __main__ - ERROR - Error loading model from C:/Users/shash/Documents/GitHub/adhd-assessment-system/backend/mlmodels/it21288326/adhd_model.keras: Error when deserializing class 'InputLayer' using config={'batch_shape': [None, 7], 'dtype': 'float32', 'sparse': False, 'name': 'input_layer'}.

Exception encountered: Unrecognized keyword arguments: ['batch_shape']
2025-04-07 23:41:53,426 - __main__ - ERROR - Error loading model from fallback location: No file or directory found at adhd_model_fallback.keras
2025-04-07 23:41:53,426 - __main__ - ERROR - Error: Could not load model. Please train the model first.
2025-04-07 23:41:53,427 - __main__ - INFO - Starting prediction service on http://localhost:5000
2025-04-07 23:41:53,438 - werkzeug - INFO - [31m[1mWARNING: This is a development server. Do not use it in a production deployment. Use a production WSGI server instead.[0m
 * Running on all addresses (0.0.0.0)
 * Running on http://127.0.0.1:5000
 * Running on http://192.168.8.237:5000
2025-04-07 23:41:53,439 - werkzeug - INFO - [33mPress CTRL+C to quit[0m
2025-04-07 23:44:38,133 - __main__ - INFO - MongoDB connection established successfully
2025-04-07 23:44:38,276 - __main__ - ERROR - Error loading model from C:/Users/shash/Documents/GitHub/adhd-assessment-system/backend/mlmodels/it21288326/adhd_model.keras: Error when deserializing class 'InputLayer' using config={'batch_shape': [None, 7], 'dtype': 'float32', 'sparse': False, 'name': 'input_layer'}.

Exception encountered: Unrecognized keyword arguments: ['batch_shape']
2025-04-07 23:44:38,277 - __main__ - ERROR - Error loading model from fallback location: No file or directory found at adhd_model_fallback.keras
2025-04-07 23:44:38,277 - __main__ - ERROR - Error: Could not load model. Please train the model first.
2025-04-07 23:44:38,278 - __main__ - INFO - Starting prediction service on http://localhost:5000
2025-04-07 23:44:38,318 - werkzeug - INFO - [31m[1mWARNING: This is a development server. Do not use it in a production deployment. Use a production WSGI server instead.[0m
 * Running on all addresses (0.0.0.0)
 * Running on http://127.0.0.1:5000
 * Running on http://192.168.8.237:5000
2025-04-07 23:44:38,318 - werkzeug - INFO - [33mPress CTRL+C to quit[0m
2025-04-07 23:49:16,817 - __main__ - INFO - MongoDB connection established successfully
2025-04-07 23:49:16,903 - __main__ - ERROR - Error loading model from C:/Users/shash/Documents/GitHub/adhd-assessment-system/backend/mlmodels/it21288326/adhd_model.keras: Error when deserializing class 'InputLayer' using config={'batch_shape': [None, 7], 'dtype': 'float32', 'sparse': False, 'name': 'input_layer'}.

Exception encountered: Unrecognized keyword arguments: ['batch_shape']
2025-04-07 23:49:16,904 - __main__ - ERROR - Error loading model from fallback location: No file or directory found at adhd_model_fallback.keras
2025-04-07 23:49:16,904 - __main__ - ERROR - Error: Could not load model. Please train the model first.
2025-04-07 23:49:16,904 - __main__ - INFO - Starting prediction service on http://localhost:5000
2025-04-07 23:49:16,918 - werkzeug - INFO - [31m[1mWARNING: This is a development server. Do not use it in a production deployment. Use a production WSGI server instead.[0m
 * Running on all addresses (0.0.0.0)
 * Running on http://127.0.0.1:5000
 * Running on http://192.168.8.237:5000
2025-04-07 23:49:16,918 - werkzeug - INFO - [33mPress CTRL+C to quit[0m
2025-04-07 23:55:21,330 - werkzeug - INFO - 127.0.0.1 - - [07/Apr/2025 23:55:21] "GET /health HTTP/1.1" 200 -
2025-04-07 23:55:21,691 - werkzeug - INFO - 127.0.0.1 - - [07/Apr/2025 23:55:21] "GET /health HTTP/1.1" 200 -
2025-04-08 00:00:21,509 - werkzeug - INFO - 127.0.0.1 - - [08/Apr/2025 00:00:21] "GET /health HTTP/1.1" 200 -
2025-04-08 00:05:21,350 - werkzeug - INFO - 127.0.0.1 - - [08/Apr/2025 00:05:21] "GET /health HTTP/1.1" 200 -
2025-04-08 00:10:21,403 - werkzeug - INFO - 127.0.0.1 - - [08/Apr/2025 00:10:21] "GET /health HTTP/1.1" 200 -
2025-04-08 00:15:21,346 - werkzeug - INFO - 127.0.0.1 - - [08/Apr/2025 00:15:21] "GET /health HTTP/1.1" 200 -
2025-04-08 00:20:21,452 - werkzeug - INFO - 127.0.0.1 - - [08/Apr/2025 00:20:21] "GET /health HTTP/1.1" 200 -
2025-04-08 00:25:21,353 - werkzeug - INFO - 127.0.0.1 - - [08/Apr/2025 00:25:21] "GET /health HTTP/1.1" 200 -
2025-04-08 00:30:21,318 - werkzeug - INFO - 127.0.0.1 - - [08/Apr/2025 00:30:21] "GET /health HTTP/1.1" 200 -
2025-04-08 00:35:21,343 - werkzeug - INFO - 127.0.0.1 - - [08/Apr/2025 00:35:21] "GET /health HTTP/1.1" 200 -
2025-04-08 00:40:21,311 - werkzeug - INFO - 127.0.0.1 - - [08/Apr/2025 00:40:21] "GET /health HTTP/1.1" 200 -
2025-04-08 00:45:21,398 - werkzeug - INFO - 127.0.0.1 - - [08/Apr/2025 00:45:21] "GET /health HTTP/1.1" 200 -
2025-04-08 00:50:21,437 - werkzeug - INFO - 127.0.0.1 - - [08/Apr/2025 00:50:21] "GET /health HTTP/1.1" 200 -
2025-04-08 00:55:21,471 - werkzeug - INFO - 127.0.0.1 - - [08/Apr/2025 00:55:21] "GET /health HTTP/1.1" 200 -
2025-04-08 01:00:21,521 - werkzeug - INFO - 127.0.0.1 - - [08/Apr/2025 01:00:21] "GET /health HTTP/1.1" 200 -
2025-04-08 01:05:21,321 - werkzeug - INFO - 127.0.0.1 - - [08/Apr/2025 01:05:21] "GET /health HTTP/1.1" 200 -
2025-04-08 01:10:21,364 - werkzeug - INFO - 127.0.0.1 - - [08/Apr/2025 01:10:21] "GET /health HTTP/1.1" 200 -
2025-04-08 01:15:21,323 - werkzeug - INFO - 127.0.0.1 - - [08/Apr/2025 01:15:21] "GET /health HTTP/1.1" 200 -
2025-04-08 01:20:21,425 - werkzeug - INFO - 127.0.0.1 - - [08/Apr/2025 01:20:21] "GET /health HTTP/1.1" 200 -
2025-04-08 01:25:21,456 - werkzeug - INFO - 127.0.0.1 - - [08/Apr/2025 01:25:21] "GET /health HTTP/1.1" 200 -
2025-04-08 01:30:21,295 - werkzeug - INFO - 127.0.0.1 - - [08/Apr/2025 01:30:21] "GET /health HTTP/1.1" 200 -
2025-04-08 01:35:21,322 - werkzeug - INFO - 127.0.0.1 - - [08/Apr/2025 01:35:21] "GET /health HTTP/1.1" 200 -
2025-04-08 01:40:21,724 - werkzeug - INFO - 127.0.0.1 - - [08/Apr/2025 01:40:21] "GET /health HTTP/1.1" 200 -
2025-04-08 01:45:21,382 - werkzeug - INFO - 127.0.0.1 - - [08/Apr/2025 01:45:21] "GET /health HTTP/1.1" 200 -
2025-04-08 01:50:21,405 - werkzeug - INFO - 127.0.0.1 - - [08/Apr/2025 01:50:21] "GET /health HTTP/1.1" 200 -
2025-04-08 01:55:21,397 - werkzeug - INFO - 127.0.0.1 - - [08/Apr/2025 01:55:21] "GET /health HTTP/1.1" 200 -
2025-04-08 02:00:21,488 - werkzeug - INFO - 127.0.0.1 - - [08/Apr/2025 02:00:21] "GET /health HTTP/1.1" 200 -
2025-04-08 02:05:21,503 - werkzeug - INFO - 127.0.0.1 - - [08/Apr/2025 02:05:21] "GET /health HTTP/1.1" 200 -
2025-04-08 02:10:21,347 - werkzeug - INFO - 127.0.0.1 - - [08/Apr/2025 02:10:21] "GET /health HTTP/1.1" 200 -
2025-04-08 02:15:21,556 - werkzeug - INFO - 127.0.0.1 - - [08/Apr/2025 02:15:21] "GET /health HTTP/1.1" 200 -
2025-04-08 02:20:21,399 - werkzeug - INFO - 127.0.0.1 - - [08/Apr/2025 02:20:21] "GET /health HTTP/1.1" 200 -
2025-04-08 02:25:21,458 - werkzeug - INFO - 127.0.0.1 - - [08/Apr/2025 02:25:21] "GET /health HTTP/1.1" 200 -
2025-04-08 02:30:21,387 - werkzeug - INFO - 127.0.0.1 - - [08/Apr/2025 02:30:21] "GET /health HTTP/1.1" 200 -
2025-04-08 02:35:21,498 - werkzeug - INFO - 127.0.0.1 - - [08/Apr/2025 02:35:21] "GET /health HTTP/1.1" 200 -
2025-04-08 02:40:21,330 - werkzeug - INFO - 127.0.0.1 - - [08/Apr/2025 02:40:21] "GET /health HTTP/1.1" 200 -
2025-04-08 06:55:11,049 - werkzeug - INFO - 127.0.0.1 - - [08/Apr/2025 06:55:11] "GET /health HTTP/1.1" 200 -
2025-04-08 06:55:24,502 - werkzeug - INFO - 127.0.0.1 - - [08/Apr/2025 06:55:24] "GET /health HTTP/1.1" 200 -
2025-04-08 07:00:21,649 - werkzeug - INFO - 127.0.0.1 - - [08/Apr/2025 07:00:21] "GET /health HTTP/1.1" 200 -
2025-04-08 07:05:21,495 - werkzeug - INFO - 127.0.0.1 - - [08/Apr/2025 07:05:21] "GET /health HTTP/1.1" 200 -
2025-04-08 07:26:34,753 - werkzeug - INFO - 127.0.0.1 - - [08/Apr/2025 07:26:34] "GET /health HTTP/1.1" 200 -
2025-04-08 07:30:21,661 - werkzeug - INFO - 127.0.0.1 - - [08/Apr/2025 07:30:21] "GET /health HTTP/1.1" 200 -
2025-04-08 07:35:21,600 - werkzeug - INFO - 127.0.0.1 - - [08/Apr/2025 07:35:21] "GET /health HTTP/1.1" 200 -
2025-04-08 07:40:21,610 - werkzeug - INFO - 127.0.0.1 - - [08/Apr/2025 07:40:21] "GET /health HTTP/1.1" 200 -
2025-04-08 07:45:21,521 - werkzeug - INFO - 127.0.0.1 - - [08/Apr/2025 07:45:21] "GET /health HTTP/1.1" 200 -
2025-04-08 07:50:21,422 - werkzeug - INFO - 127.0.0.1 - - [08/Apr/2025 07:50:21] "GET /health HTTP/1.1" 200 -
2025-04-08 07:55:21,444 - werkzeug - INFO - 127.0.0.1 - - [08/Apr/2025 07:55:21] "GET /health HTTP/1.1" 200 -
2025-04-08 08:00:21,496 - werkzeug - INFO - 127.0.0.1 - - [08/Apr/2025 08:00:21] "GET /health HTTP/1.1" 200 -
2025-04-08 08:05:21,425 - werkzeug - INFO - 127.0.0.1 - - [08/Apr/2025 08:05:21] "GET /health HTTP/1.1" 200 -
2025-04-08 08:10:21,472 - werkzeug - INFO - 127.0.0.1 - - [08/Apr/2025 08:10:21] "GET /health HTTP/1.1" 200 -
2025-04-08 10:01:53,589 - werkzeug - INFO - 127.0.0.1 - - [08/Apr/2025 10:01:53] "GET /health HTTP/1.1" 200 -
2025-04-08 10:02:03,452 - werkzeug - INFO - 127.0.0.1 - - [08/Apr/2025 10:02:03] "GET /health HTTP/1.1" 200 -
2025-04-08 10:05:23,259 - werkzeug - INFO - 127.0.0.1 - - [08/Apr/2025 10:05:23] "GET /health HTTP/1.1" 200 -
2025-04-08 10:10:21,500 - werkzeug - INFO - 127.0.0.1 - - [08/Apr/2025 10:10:21] "GET /health HTTP/1.1" 200 -
2025-04-08 10:15:21,328 - werkzeug - INFO - 127.0.0.1 - - [08/Apr/2025 10:15:21] "GET /health HTTP/1.1" 200 -
2025-04-08 10:20:21,333 - werkzeug - INFO - 127.0.0.1 - - [08/Apr/2025 10:20:21] "GET /health HTTP/1.1" 200 -
2025-04-08 10:25:21,393 - werkzeug - INFO - 127.0.0.1 - - [08/Apr/2025 10:25:21] "GET /health HTTP/1.1" 200 -
2025-04-08 10:30:21,429 - werkzeug - INFO - 127.0.0.1 - - [08/Apr/2025 10:30:21] "GET /health HTTP/1.1" 200 -
2025-04-08 10:35:21,459 - werkzeug - INFO - 127.0.0.1 - - [08/Apr/2025 10:35:21] "GET /health HTTP/1.1" 200 -
2025-04-08 10:46:20,853 - werkzeug - INFO - 127.0.0.1 - - [08/Apr/2025 10:46:20] "GET /health HTTP/1.1" 200 -
2025-04-08 10:50:21,361 - werkzeug - INFO - 127.0.0.1 - - [08/Apr/2025 10:50:21] "GET /health HTTP/1.1" 200 -
2025-04-08 10:55:21,351 - werkzeug - INFO - 127.0.0.1 - - [08/Apr/2025 10:55:21] "GET /health HTTP/1.1" 200 -
2025-04-08 11:00:21,373 - werkzeug - INFO - 127.0.0.1 - - [08/Apr/2025 11:00:21] "GET /health HTTP/1.1" 200 -
2025-04-08 11:05:21,609 - werkzeug - INFO - 127.0.0.1 - - [08/Apr/2025 11:05:21] "GET /health HTTP/1.1" 200 -
2025-04-08 11:28:02,584 - werkzeug - INFO - 127.0.0.1 - - [08/Apr/2025 11:28:02] "GET /health HTTP/1.1" 200 -
2025-04-10 20:34:14,223 - __main__ - INFO - MongoDB connection established successfully
2025-04-10 20:34:14,899 - __main__ - ERROR - Error loading model from C:/Users/shash/Documents/GitHub/adhd-assessment-system/backend/mlmodels/it21288326/adhd_model.keras: Error when deserializing class 'InputLayer' using config={'batch_shape': [None, 7], 'dtype': 'float32', 'sparse': False, 'name': 'input_layer'}.

Exception encountered: Unrecognized keyword arguments: ['batch_shape']
2025-04-10 20:34:14,905 - __main__ - ERROR - Error loading model from fallback location: No file or directory found at adhd_model_fallback.keras
2025-04-10 20:34:14,905 - __main__ - ERROR - Error: Could not load model. Please train the model first.
2025-04-10 20:34:14,909 - __main__ - INFO - Starting prediction service on http://localhost:5000
2025-04-10 20:34:14,994 - werkzeug - INFO - [31m[1mWARNING: This is a development server. Do not use it in a production deployment. Use a production WSGI server instead.[0m
 * Running on all addresses (0.0.0.0)
 * Running on http://127.0.0.1:5000
 * Running on http://192.168.8.237:5000
2025-04-10 20:34:14,995 - werkzeug - INFO - [33mPress CTRL+C to quit[0m
2025-04-10 20:35:13,605 - werkzeug - INFO - 127.0.0.1 - - [10/Apr/2025 20:35:13] "GET /health HTTP/1.1" 200 -
2025-04-10 20:35:13,864 - werkzeug - INFO - 127.0.0.1 - - [10/Apr/2025 20:35:13] "GET /health HTTP/1.1" 200 -
